<sdf version='1.6'>
  <world name='default'>
    <light name='sun' type='directional'>
      <cast_shadows>1</cast_shadows>
      <pose frame=''>0 0 10 0 -0 0</pose>
      <diffuse>0.8 0.8 0.8 1</diffuse>
      <specular>0.2 0.2 0.2 1</specular>
      <attenuation>
        <range>1000</range>
        <constant>0.9</constant>
        <linear>0.01</linear>
        <quadratic>0.001</quadratic>
      </attenuation>
      <direction>-0.5 0.1 -0.9</direction>
    </light>
    <model name='ground_plane'>
      <static>1</static>
      <link name='link'>
        <collision name='collision'>
          <geometry>
            <plane>
              <normal>0 0 1</normal>
              <size>100 100</size>
            </plane>
          </geometry>
          <surface>
            <contact>
              <collide_bitmask>65535</collide_bitmask>
              <ode/>
            </contact>
            <friction>
              <ode>
                <mu>100</mu>
                <mu2>50</mu2>
              </ode>
              <torsional>
                <ode/>
              </torsional>
            </friction>
            <bounce/>
          </surface>
          <max_contacts>10</max_contacts>
        </collision>
        <visual name='visual'>
          <cast_shadows>0</cast_shadows>
          <geometry>
            <plane>
              <normal>0 0 1</normal>
              <size>100 100</size>
            </plane>
          </geometry>
          <material>
            <script>
              <uri>file://media/materials/scripts/gazebo.material</uri>
              <name>Gazebo/Grey</name>
            </script>
          </material>
        </visual>
        <self_collide>0</self_collide>
        <kinematic>0</kinematic>
      </link>
    </model>
    <gravity>0 0 -9.8</gravity>
    <magnetic_field>6e-06 2.3e-05 -4.2e-05</magnetic_field>
    <atmosphere type='adiabatic'/>
    <physics name='default_physics' default='0' type='ode'>
      <max_step_size>0.001</max_step_size>
      <real_time_factor>1</real_time_factor>
      <real_time_update_rate>1000</real_time_update_rate>
    </physics>
    <scene>
      <ambient>0.4 0.4 0.4 1</ambient>
      <background>0.7 0.7 0.7 1</background>
      <shadows>1</shadows>
    </scene>
    <spherical_coordinates>
      <surface_model>EARTH_WGS84</surface_model>
      <latitude_deg>0</latitude_deg>
      <longitude_deg>0</longitude_deg>
      <elevation>0</elevation>
      <heading_deg>0</heading_deg>
    </spherical_coordinates>
    <model name='movo'>
      <link name='base_link'>
        <pose frame=''>0 0 0 0 -0 0</pose>
        <inertial>
          <pose frame=''>-0.002974 -0.008419 0.237851 0 -0 0</pose>
          <mass>67.9184</mass>
          <inertia>
            <ixx>3.97207</ixx>
            <ixy>-0.00341811</ixy>
            <ixz>-0.0764064</ixz>
            <iyy>4.23328</iyy>
            <iyz>-0.075981</iyz>
            <izz>0.697625</izz>
          </inertia>
        </inertial>
        <collision name='base_link_fixed_joint_lump__base_chassis_link_collision'>
          <pose frame=''>0 0 0.0762 0 -0 0</pose>
          <geometry>
            <mesh>
              <scale>1 1 1</scale>
              <uri>/home/jeff/movo_ws/src/kinova-movo/movo_common/movo_description/meshes/movo_components/collision/vector_base_collision.stl</uri>
            </mesh>
          </geometry>
          <surface>
            <contact>
              <ode/>
            </contact>
            <friction>
              <ode>
                <mu>0</mu>
              </ode>
              <torsional>
                <ode/>
              </torsional>
            </friction>
            <bounce/>
          </surface>
          <laser_retro>0</laser_retro>
          <max_contacts>10</max_contacts>
        </collision>
        <collision name='base_link_fixed_joint_lump__front_laser_link_collision_1'>
          <pose frame=''>0.3375 0 0.220111 3.14159 -0 0</pose>
          <geometry>
            <box>
              <size>0.1 0.1 0.1</size>
            </box>
          </geometry>
          <surface>
            <contact>
              <ode/>
            </contact>
            <friction>
              <ode/>
              <torsional>
                <ode/>
              </torsional>
            </friction>
            <bounce/>
          </surface>
          <max_contacts>10</max_contacts>
        </collision>
        <collision name='base_link_fixed_joint_lump__linear_actuator_fixed_link_collision_2'>
          <pose frame=''>0 0 0.0762 0 -0 0</pose>
          <geometry>
            <mesh>
              <scale>1 1 1</scale>
              <uri>/home/jeff/movo_ws/src/kinova-movo/movo_common/movo_description/meshes/movo_components/collision/movo_fixed_body_collision.stl</uri>
            </mesh>
          </geometry>
          <surface>
            <contact>
              <ode/>
            </contact>
            <friction>
              <ode/>
              <torsional>
                <ode/>
              </torsional>
            </friction>
            <bounce/>
          </surface>
          <laser_retro>0</laser_retro>
          <max_contacts>10</max_contacts>
        </collision>
        <collision name='base_link_fixed_joint_lump__rear_laser_link_collision_3'>
          <pose frame=''>-0.3375 0 0.220111 3.14159 -0 3.14159</pose>
          <geometry>
            <box>
              <size>0.1 0.1 0.1</size>
            </box>
          </geometry>
          <surface>
            <contact>
              <ode/>
            </contact>
            <friction>
              <ode/>
              <torsional>
                <ode/>
              </torsional>
            </friction>
            <bounce/>
          </surface>
          <max_contacts>10</max_contacts>
        </collision>
        <visual name='base_link_fixed_joint_lump__base_chassis_link_visual'>
          <pose frame=''>0 0 0.0762 0 -0 0</pose>
          <geometry>
            <mesh>
              <scale>1 1 1</scale>
              <uri>/home/jeff/movo_ws/src/kinova-movo/movo_common/movo_description/meshes/movo_components/visual/vector_base.dae</uri>
            </mesh>
          </geometry>
          <material>
            <script>
              <uri>__default__</uri>
              <name>__default__</name>
            </script>
          </material>
        </visual>
        <visual name='base_link_fixed_joint_lump__front_laser_link_visual_1'>
          <pose frame=''>0.3375 0 0.220111 3.14159 -0 0</pose>
          <geometry>
            <mesh>
              <scale>1 1 1</scale>
              <uri>/home/jeff/movo_ws/src/kinova-movo/movo_common/movo_description/meshes/sensors/visual/sick_tim.dae</uri>
            </mesh>
          </geometry>
          <material>
            <script>
              <uri>__default__</uri>
              <name>__default__</name>
            </script>
          </material>
        </visual>
        <visual name='base_link_fixed_joint_lump__linear_actuator_fixed_link_visual_2'>
          <pose frame=''>0 0 0.0762 0 -0 0</pose>
          <geometry>
            <mesh>
              <scale>1 1 1</scale>
              <uri>/home/jeff/movo_ws/src/kinova-movo/movo_common/movo_description/meshes/movo_components/visual/movo_fixed_payload.dae</uri>
            </mesh>
          </geometry>
          <material>
            <script>
              <uri>__default__</uri>
              <name>__default__</name>
            </script>
          </material>
        </visual>
        <visual name='base_link_fixed_joint_lump__lower_body_link_visual_3'>
          <pose frame=''>0 0 0.0762 0 -0 0</pose>
          <geometry>
            <mesh>
              <scale>1 1 1</scale>
              <uri>/home/jeff/movo_ws/src/kinova-movo/movo_common/movo_description/meshes/movo_body/movo_lower_body.dae</uri>
            </mesh>
          </geometry>
        </visual>
        <visual name='base_link_fixed_joint_lump__rear_laser_link_visual_4'>
          <pose frame=''>-0.3375 0 0.220111 3.14159 -0 3.14159</pose>
          <geometry>
            <mesh>
              <scale>1 1 1</scale>
              <uri>/home/jeff/movo_ws/src/kinova-movo/movo_common/movo_description/meshes/sensors/visual/sick_tim.dae</uri>
            </mesh>
          </geometry>
          <material>
            <script>
              <uri>__default__</uri>
              <name>__default__</name>
            </script>
          </material>
        </visual>
        <velocity_decay/>
        <velocity_decay/>
        <velocity_decay/>
        <velocity_decay/>
        <sensor name='front_laser' type='ray'>
          <visualize>0</visualize>
          <update_rate>15</update_rate>
          <ray>
            <scan>
              <horizontal>
                <samples>720</samples>
                <resolution>1</resolution>
                <min_angle>-2</min_angle>
                <max_angle>2</max_angle>
              </horizontal>
              <vertical>
                <samples>1</samples>
                <min_angle>0</min_angle>
                <max_angle>0</max_angle>
              </vertical>
            </scan>
            <range>
              <min>0.1</min>
              <max>25</max>
              <resolution>0.01</resolution>
            </range>
            <noise>
              <type>gaussian</type>
              <mean>0</mean>
              <stddev>0.01</stddev>
            </noise>
          </ray>
          <plugin name='front_laser_node' filename='libgazebo_ros_laser.so'>
            <topicName>/movo/front_scan</topicName>
            <frameName>front_laser_link</frameName>
            <robotNamespace>/</robotNamespace>
          </plugin>
          <pose frame=''>0.3375 0 0.220111 3.14159 -0 0</pose>
        </sensor>
        <velocity_decay/>
        <gravity>1</gravity>
        <velocity_decay/>
        <sensor name='rear_laser' type='ray'>
          <visualize>0</visualize>
          <update_rate>15</update_rate>
          <ray>
            <scan>
              <horizontal>
                <samples>720</samples>
                <resolution>1</resolution>
                <min_angle>-2</min_angle>
                <max_angle>2</max_angle>
              </horizontal>
              <vertical>
                <samples>1</samples>
                <min_angle>0</min_angle>
                <max_angle>0</max_angle>
              </vertical>
            </scan>
            <range>
              <min>0.1</min>
              <max>25</max>
              <resolution>0.01</resolution>
            </range>
            <noise>
              <type>gaussian</type>
              <mean>0</mean>
              <stddev>0.01</stddev>
            </noise>
          </ray>
          <plugin name='rear_laser_node' filename='libgazebo_ros_laser.so'>
            <topicName>/movo/rear_scan</topicName>
            <frameName>rear_laser_link</frameName>
            <robotNamespace>/</robotNamespace>
          </plugin>
          <pose frame=''>-0.3375 0 0.220111 3.14159 -0 3.14159</pose>
        </sensor>
        <self_collide>0</self_collide>
        <kinematic>0</kinematic>
      </link>
      <link name='linear_actuator_link'>
        <pose frame=''>0.07714 0 0.470076 0 -0 0</pose>
        <inertial>
          <pose frame=''>-0.06514 -0.002828 0.356497 0 -0 0</pose>
          <mass>20.7437</mass>
          <inertia>
            <ixx>0.8115</ixx>
            <ixy>-0.0106441</ixy>
            <ixz>-0.0608701</ixz>
            <iyy>0.839619</iyy>
            <iyz>-0.022887</iyz>
            <izz>0.666234</izz>
          </inertia>
        </inertial>
        <collision name='linear_actuator_link_collision'>
          <pose frame=''>0 0 0 0 -0 0</pose>
          <geometry>
            <mesh>
              <scale>1 1 1</scale>
              <uri>/home/jeff/movo_ws/src/kinova-movo/movo_common/movo_description/meshes/movo_components/collision/movo_upper_body_collision.stl</uri>
            </mesh>
          </geometry>
          <surface>
            <contact>
              <ode/>
            </contact>
            <friction>
              <ode/>
              <torsional>
                <ode/>
              </torsional>
            </friction>
            <bounce/>
          </surface>
          <laser_retro>0</laser_retro>
          <max_contacts>10</max_contacts>
        </collision>
        <collision name='linear_actuator_link_fixed_joint_lump__left_base_link_collision_1'>
          <pose frame=''>0.026105 0.13335 0.279994 -1.5708 -0 -1.5708</pose>
          <geometry>
            <mesh>
              <scale>1 1 1</scale>
              <uri>/home/jeff/movo_ws/src/kinova-movo/movo_common/movo_description/meshes/manipulation/jaco/collision/base.stl</uri>
            </mesh>
          </geometry>
          <surface>
            <contact>
              <ode>
                <kp>1e+06</kp>
                <kd>100</kd>
                <max_vel>100</max_vel>
                <min_depth>0.001</min_depth>
              </ode>
            </contact>
            <friction>
              <ode>
                <mu>1</mu>
                <mu2>1</mu2>
              </ode>
              <torsional>
                <ode/>
              </torsional>
            </friction>
            <bounce/>
          </surface>
          <max_contacts>10</max_contacts>
        </collision>
        <collision name='linear_actuator_link_fixed_joint_lump__pan_base_link_collision_2'>
          <pose frame=''>0.19735 0 0.344989 0 -0 0</pose>
          <geometry>
            <mesh>
              <scale>1 1 1</scale>
              <uri>/home/jeff/movo_ws/src/kinova-movo/movo_common/movo_description/meshes/pan_tilt/collision/pan_tilt_base.stl</uri>
            </mesh>
          </geometry>
          <max_contacts>10</max_contacts>
          <surface>
            <contact>
              <ode/>
            </contact>
            <bounce/>
            <friction>
              <torsional>
                <ode/>
              </torsional>
              <ode/>
            </friction>
          </surface>
        </collision>
        <collision name='linear_actuator_link_fixed_joint_lump__right_base_link_collision_3'>
          <pose frame=''>0.026105 -0.13335 0.279994 -1.5708 -0 -1.5708</pose>
          <geometry>
            <mesh>
              <scale>1 1 1</scale>
              <uri>/home/jeff/movo_ws/src/kinova-movo/movo_common/movo_description/meshes/manipulation/jaco/collision/base.stl</uri>
            </mesh>
          </geometry>
          <surface>
            <contact>
              <ode>
                <kp>1e+06</kp>
                <kd>100</kd>
                <max_vel>100</max_vel>
                <min_depth>0.001</min_depth>
              </ode>
            </contact>
            <friction>
              <ode>
                <mu>1</mu>
                <mu2>1</mu2>
              </ode>
              <torsional>
                <ode/>
              </torsional>
            </friction>
            <bounce/>
          </surface>
          <max_contacts>10</max_contacts>
        </collision>
        <visual name='linear_actuator_link_visual'>
          <pose frame=''>0 0 0 0 -0 0</pose>
          <geometry>
            <mesh>
              <scale>1 1 1</scale>
              <uri>/home/jeff/movo_ws/src/kinova-movo/movo_common/movo_description/meshes/movo_components/visual/movo_moving_payload.dae</uri>
            </mesh>
          </geometry>
          <material>
            <script>
              <uri>__default__</uri>
              <name>__default__</name>
            </script>
          </material>
        </visual>
        <visual name='linear_actuator_link_fixed_joint_lump__left_base_link_visual_1'>
          <pose frame=''>0.026105 0.13335 0.279994 -1.5708 -0 -1.5708</pose>
          <geometry>
            <mesh>
              <scale>1 1 1</scale>
              <uri>/home/jeff/movo_ws/src/kinova-movo/movo_common/movo_description/meshes/manipulation/jaco/visual/base.dae</uri>
            </mesh>
          </geometry>
          <material>
            <script>
              <uri>__default__</uri>
              <name>__default__</name>
            </script>
          </material>
        </visual>
        <visual name='linear_actuator_link_fixed_joint_lump__pan_base_link_visual_2'>
          <pose frame=''>0.19735 0 0.344989 0 -0 0</pose>
          <geometry>
            <mesh>
              <scale>1 1 1</scale>
              <uri>/home/jeff/movo_ws/src/kinova-movo/movo_common/movo_description/meshes/pan_tilt/visual/pan_tilt_base.dae</uri>
            </mesh>
          </geometry>
        </visual>
        <visual name='linear_actuator_link_fixed_joint_lump__right_base_link_visual_3'>
          <pose frame=''>0.026105 -0.13335 0.279994 -1.5708 -0 -1.5708</pose>
          <geometry>
            <mesh>
              <scale>1 1 1</scale>
              <uri>/home/jeff/movo_ws/src/kinova-movo/movo_common/movo_description/meshes/manipulation/jaco/visual/base.dae</uri>
            </mesh>
          </geometry>
          <material>
            <script>
              <uri>__default__</uri>
              <name>__default__</name>
            </script>
          </material>
        </visual>
        <visual name='linear_actuator_link_fixed_joint_lump__upper_body_link_visual_4'>
          <pose frame=''>0 0 0 0 -0 0</pose>
          <geometry>
            <mesh>
              <scale>1 1 1</scale>
              <uri>/home/jeff/movo_ws/src/kinova-movo/movo_common/movo_description/meshes/movo_body/movo_upper_body.dae</uri>
            </mesh>
          </geometry>
        </visual>
        <velocity_decay/>
        <velocity_decay/>
        <gravity>1</gravity>
        <velocity_decay/>
        <self_collide>0</self_collide>
        <kinematic>0</kinematic>
      </link>
      <joint name='linear_joint' type='prismatic'>
        <child>linear_actuator_link</child>
        <parent>base_link</parent>
        <axis>
          <xyz>0 0 1</xyz>
          <limit>
            <lower>0</lower>
            <upper>0.472</upper>
            <effort>1000</effort>
            <velocity>0.2</velocity>
          </limit>
          <dynamics>
            <damping>0</damping>
            <friction>0</friction>
            <spring_reference>0</spring_reference>
            <spring_stiffness>0</spring_stiffness>
          </dynamics>
          <use_parent_model_frame>1</use_parent_model_frame>
        </axis>
      </joint>
      <link name='left_shoulder_link'>
        <pose frame=''>0.165745 0.13335 0.75007 -1.5708 0 1.5708</pose>
        <inertial>
          <pose frame=''>1.8e-05 -0.004667 -0.060609 0 -0 0</pose>
          <mass>0.824524</mass>
          <inertia>
            <ixx>0.002561</ixx>
            <ixy>0</ixy>
            <ixz>1e-06</ixz>
            <iyy>0.002653</iyy>
            <iyz>0.000212</iyz>
            <izz>0.000524</izz>
          </inertia>
        </inertial>
        <collision name='left_shoulder_link_collision'>
          <pose frame=''>0 0 0 0 -0 0</pose>
          <geometry>
            <mesh>
              <scale>1 1 1</scale>
              <uri>/home/jeff/movo_ws/src/kinova-movo/movo_common/movo_description/meshes/manipulation/jaco/collision/shoulder_7dof.stl</uri>
            </mesh>
          </geometry>
          <surface>
            <contact>
              <ode>
                <kp>1e+06</kp>
                <kd>100</kd>
                <max_vel>100</max_vel>
                <min_depth>0.001</min_depth>
              </ode>
            </contact>
            <friction>
              <ode>
                <mu>1</mu>
                <mu2>1</mu2>
              </ode>
              <torsional>
                <ode/>
              </torsional>
            </friction>
            <bounce/>
          </surface>
          <max_contacts>10</max_contacts>
        </collision>
        <visual name='left_shoulder_link_visual'>
          <pose frame=''>0 0 0 0 -0 0</pose>
          <geometry>
            <mesh>
              <scale>1 1 1</scale>
              <uri>/home/jeff/movo_ws/src/kinova-movo/movo_common/movo_description/meshes/manipulation/jaco/visual/shoulder_7dof.dae</uri>
            </mesh>
          </geometry>
          <material>
            <script>
              <uri>__default__</uri>
              <name>__default__</name>
            </script>
          </material>
        </visual>
        <gravity>1</gravity>
        <velocity_decay/>
        <self_collide>0</self_collide>
        <kinematic>0</kinematic>
      </link>
      <joint name='left_shoulder_pan_joint' type='revolute'>
        <child>left_shoulder_link</child>
        <parent>linear_actuator_link</parent>
        <axis>
          <xyz>-1 0 0</xyz>
          <limit>
            <lower>-3.14159</lower>
            <upper>3.14159</upper>
            <effort>18000</effort>
            <velocity>0.69115</velocity>
          </limit>
          <dynamics>
            <damping>0.01</damping>
            <friction>0</friction>
            <spring_reference>0</spring_reference>
            <spring_stiffness>0</spring_stiffness>
          </dynamics>
          <use_parent_model_frame>1</use_parent_model_frame>
        </axis>
      </joint>
      <link name='left_arm_half_1_link'>
        <pose frame=''>0.284495 0.13335 0.75007 0 -0 1.5708</pose>
        <inertial>
          <pose frame=''>0 -0.103563 0 0 -0 0</pose>
          <mass>0.8447</mass>
          <inertia>
            <ixx>0.000435</ixx>
            <ixy>2e-06</ixy>
            <ixz>0.000231</ixz>
            <iyy>0.034947</iyy>
            <iyz>0</iyz>
            <izz>0.035198</izz>
          </inertia>
        </inertial>
        <collision name='left_arm_half_1_link_collision'>
          <pose frame=''>0 0 0 0 -0 0</pose>
          <geometry>
            <mesh>
              <scale>1 1 1</scale>
              <uri>/home/jeff/movo_ws/src/kinova-movo/movo_common/movo_description/meshes/manipulation/jaco/collision/arm_half_1.stl</uri>
            </mesh>
          </geometry>
          <surface>
            <contact>
              <ode>
                <kp>1e+06</kp>
                <kd>100</kd>
                <max_vel>100</max_vel>
                <min_depth>0.001</min_depth>
              </ode>
            </contact>
            <friction>
              <ode>
                <mu>1</mu>
                <mu2>1</mu2>
              </ode>
              <torsional>
                <ode/>
              </torsional>
            </friction>
            <bounce/>
          </surface>
          <max_contacts>10</max_contacts>
        </collision>
        <visual name='left_arm_half_1_link_visual'>
          <pose frame=''>0 0 0 0 -0 0</pose>
          <geometry>
            <mesh>
              <scale>1 1 1</scale>
              <uri>/home/jeff/movo_ws/src/kinova-movo/movo_common/movo_description/meshes/manipulation/jaco/visual/arm_half_1.dae</uri>
            </mesh>
          </geometry>
          <material>
            <script>
              <uri>__default__</uri>
              <name>__default__</name>
            </script>
          </material>
        </visual>
        <gravity>1</gravity>
        <velocity_decay/>
        <self_collide>0</self_collide>
        <kinematic>0</kinematic>
      </link>
      <joint name='left_shoulder_lift_joint' type='revolute'>
        <child>left_arm_half_1_link</child>
        <parent>left_shoulder_link</parent>
        <axis>
          <xyz>0 0 1</xyz>
          <limit>
            <lower>-2.238</lower>
            <upper>2.238</upper>
            <effort>30000.5</effort>
            <velocity>0.69115</velocity>
          </limit>
          <dynamics>
            <damping>0.01</damping>
            <friction>0</friction>
            <spring_reference>0</spring_reference>
            <spring_stiffness>0</spring_stiffness>
          </dynamics>
          <use_parent_model_frame>1</use_parent_model_frame>
        </axis>
      </joint>
      <link name='left_arm_half_2_link'>
        <pose frame=''>0.489495 0.13335 0.75007 -1.5708 0 1.5708</pose>
        <inertial>
          <pose frame=''>0 0 -0.102245 0 -0 0</pose>
          <mass>0.8447</mass>
          <inertia>
            <ixx>0.000435</ixx>
            <ixy>2e-06</ixy>
            <ixz>0.000231</ixz>
            <iyy>0.034947</iyy>
            <iyz>0</iyz>
            <izz>0.035198</izz>
          </inertia>
        </inertial>
        <collision name='left_arm_half_2_link_collision'>
          <pose frame=''>0 0 0 0 -0 0</pose>
          <geometry>
            <mesh>
              <scale>1 1 1</scale>
              <uri>/home/jeff/movo_ws/src/kinova-movo/movo_common/movo_description/meshes/manipulation/jaco/collision/arm_half_2.stl</uri>
            </mesh>
          </geometry>
          <surface>
            <contact>
              <ode>
                <kp>1e+06</kp>
                <kd>100</kd>
                <max_vel>100</max_vel>
                <min_depth>0.001</min_depth>
              </ode>
            </contact>
            <friction>
              <ode>
                <mu>1</mu>
                <mu2>1</mu2>
              </ode>
              <torsional>
                <ode/>
              </torsional>
            </friction>
            <bounce/>
          </surface>
          <max_contacts>10</max_contacts>
        </collision>
        <visual name='left_arm_half_2_link_visual'>
          <pose frame=''>0 0 0 0 -0 0</pose>
          <geometry>
            <mesh>
              <scale>1 1 1</scale>
              <uri>/home/jeff/movo_ws/src/kinova-movo/movo_common/movo_description/meshes/manipulation/jaco/visual/arm_half_2.dae</uri>
            </mesh>
          </geometry>
          <material>
            <script>
              <uri>__default__</uri>
              <name>__default__</name>
            </script>
          </material>
        </visual>
        <gravity>1</gravity>
        <velocity_decay/>
        <self_collide>0</self_collide>
        <kinematic>0</kinematic>
      </link>
      <joint name='left_arm_half_joint' type='revolute'>
        <child>left_arm_half_2_link</child>
        <parent>left_arm_half_1_link</parent>
        <axis>
          <xyz>-1 0 0</xyz>
          <limit>
            <lower>-3.14159</lower>
            <upper>3.14159</upper>
            <effort>30000.5</effort>
            <velocity>0.69115</velocity>
          </limit>
          <dynamics>
            <damping>0.01</damping>
            <friction>0</friction>
            <spring_reference>0</spring_reference>
            <spring_stiffness>0</spring_stiffness>
          </dynamics>
          <use_parent_model_frame>1</use_parent_model_frame>
        </axis>
      </joint>
      <link name='left_forearm_link'>
        <pose frame=''>0.694495 0.13335 0.75007 -3.14159 -0 1.5708</pose>
        <inertial>
          <pose frame=''>0 0.081 -0.0086 0 -0 0</pose>
          <mass>0.674254</mass>
          <inertia>
            <ixx>0.005453</ixx>
            <ixy>3e-06</ixy>
            <ixz>0</ixz>
            <iyy>0.000305</iyy>
            <iyz>8.7e-05</iyz>
            <izz>0.005578</izz>
          </inertia>
        </inertial>
        <collision name='left_forearm_link_collision'>
          <pose frame=''>0 0 0 0 -0 0</pose>
          <geometry>
            <mesh>
              <scale>1 1 1</scale>
              <uri>/home/jeff/movo_ws/src/kinova-movo/movo_common/movo_description/meshes/manipulation/jaco/collision/forearm_7dof.stl</uri>
            </mesh>
          </geometry>
          <max_contacts>10</max_contacts>
          <surface>
            <contact>
              <ode/>
            </contact>
            <bounce/>
            <friction>
              <torsional>
                <ode/>
              </torsional>
              <ode/>
            </friction>
          </surface>
        </collision>
        <visual name='left_forearm_link_visual'>
          <pose frame=''>0 0 0 0 -0 0</pose>
          <geometry>
            <mesh>
              <scale>1 1 1</scale>
              <uri>/home/jeff/movo_ws/src/kinova-movo/movo_common/movo_description/meshes/manipulation/jaco/visual/forearm_7dof.dae</uri>
            </mesh>
          </geometry>
        </visual>
        <self_collide>0</self_collide>
        <kinematic>0</kinematic>
      </link>
      <joint name='left_elbow_joint' type='revolute'>
        <child>left_forearm_link</child>
        <parent>left_arm_half_2_link</parent>
        <axis>
          <xyz>0 0 -1</xyz>
          <limit>
            <lower>-2.809</lower>
            <upper>2.809</upper>
            <effort>18000</effort>
            <velocity>0.69115</velocity>
          </limit>
          <dynamics>
            <damping>0.01</damping>
            <friction>0</friction>
            <spring_reference>0</spring_reference>
            <spring_stiffness>0</spring_stiffness>
          </dynamics>
          <use_parent_model_frame>1</use_parent_model_frame>
        </axis>
      </joint>
      <link name='left_wrist_spherical_1_link'>
        <pose frame=''>0.901795 0.13335 0.76147 1.5708 0 -1.5708</pose>
        <inertial>
          <pose frame=''>0 0.002885 -0.054193 0 -0 0</pose>
          <mass>0.463</mass>
          <inertia>
            <ixx>0.000392</ixx>
            <ixy>0</ixy>
            <ixz>0</ixz>
            <iyy>0.000347</iyy>
            <iyz>0.000101</iyz>
            <izz>0.000233</izz>
          </inertia>
        </inertial>
        <collision name='left_wrist_spherical_1_link_collision'>
          <pose frame=''>0 0 0 0 -0 0</pose>
          <geometry>
            <mesh>
              <scale>1 1 1</scale>
              <uri>/home/jeff/movo_ws/src/kinova-movo/movo_common/movo_description/meshes/manipulation/jaco/collision/wrist_spherical_1.stl</uri>
            </mesh>
          </geometry>
          <surface>
            <contact>
              <ode>
                <kp>1e+06</kp>
                <kd>100</kd>
                <max_vel>100</max_vel>
                <min_depth>0.001</min_depth>
              </ode>
            </contact>
            <friction>
              <ode>
                <mu>1</mu>
                <mu2>1</mu2>
              </ode>
              <torsional>
                <ode/>
              </torsional>
            </friction>
            <bounce/>
          </surface>
          <max_contacts>10</max_contacts>
        </collision>
        <visual name='left_wrist_spherical_1_link_visual'>
          <pose frame=''>0 0 0 0 -0 0</pose>
          <geometry>
            <mesh>
              <scale>1 1 1</scale>
              <uri>/home/jeff/movo_ws/src/kinova-movo/movo_common/movo_description/meshes/manipulation/jaco/visual/wrist_spherical_1.dae</uri>
            </mesh>
          </geometry>
          <material>
            <script>
              <uri>__default__</uri>
              <name>__default__</name>
            </script>
          </material>
        </visual>
        <gravity>1</gravity>
        <velocity_decay/>
        <self_collide>0</self_collide>
        <kinematic>0</kinematic>
      </link>
      <joint name='left_wrist_spherical_1_joint' type='revolute'>
        <child>left_wrist_spherical_1_link</child>
        <parent>left_forearm_link</parent>
        <axis>
          <xyz>-1 0 0</xyz>
          <limit>
            <lower>-3.14159</lower>
            <upper>3.14159</upper>
            <effort>60000.8</effort>
            <velocity>0.921534</velocity>
          </limit>
          <dynamics>
            <damping>0.01</damping>
            <friction>0</friction>
            <spring_reference>0</spring_reference>
            <spring_stiffness>0</spring_stiffness>
          </dynamics>
          <use_parent_model_frame>1</use_parent_model_frame>
        </axis>
      </joint>
      <link name='left_wrist_spherical_2_link'>
        <pose frame=''>1.00554 0.13335 0.76147 -0 -0 -1.5708</pose>
        <inertial>
          <pose frame=''>0 0.049721 -0.002856 0 -0 0</pose>
          <mass>0.463</mass>
          <inertia>
            <ixx>0.000392</ixx>
            <ixy>0</ixy>
            <ixz>0</ixz>
            <iyy>0.000347</iyy>
            <iyz>0.000101</iyz>
            <izz>0.000233</izz>
          </inertia>
        </inertial>
        <collision name='left_wrist_spherical_2_link_collision'>
          <pose frame=''>0 0 0 0 -0 0</pose>
          <geometry>
            <mesh>
              <scale>1 1 1</scale>
              <uri>/home/jeff/movo_ws/src/kinova-movo/movo_common/movo_description/meshes/manipulation/jaco/collision/wrist_spherical_2.stl</uri>
            </mesh>
          </geometry>
          <surface>
            <contact>
              <ode>
                <kp>1e+06</kp>
                <kd>100</kd>
                <max_vel>100</max_vel>
                <min_depth>0.001</min_depth>
              </ode>
            </contact>
            <friction>
              <ode>
                <mu>1</mu>
                <mu2>1</mu2>
              </ode>
              <torsional>
                <ode/>
              </torsional>
            </friction>
            <bounce/>
          </surface>
          <max_contacts>10</max_contacts>
        </collision>
        <visual name='left_wrist_spherical_2_link_visual'>
          <pose frame=''>0 0 0 0 -0 0</pose>
          <geometry>
            <mesh>
              <scale>1 1 1</scale>
              <uri>/home/jeff/movo_ws/src/kinova-movo/movo_common/movo_description/meshes/manipulation/jaco/visual/wrist_spherical_2.dae</uri>
            </mesh>
          </geometry>
          <material>
            <script>
              <uri>__default__</uri>
              <name>__default__</name>
            </script>
          </material>
        </visual>
        <gravity>1</gravity>
        <velocity_decay/>
        <self_collide>0</self_collide>
        <kinematic>0</kinematic>
      </link>
      <joint name='left_wrist_spherical_2_joint' type='revolute'>
        <child>left_wrist_spherical_2_link</child>
        <parent>left_wrist_spherical_1_link</parent>
        <axis>
          <xyz>0 0 1</xyz>
          <limit>
            <lower>-2.78</lower>
            <upper>2.78</upper>
            <effort>60000.8</effort>
            <velocity>0.921534</velocity>
          </limit>
          <dynamics>
            <damping>0.01</damping>
            <friction>0</friction>
            <spring_reference>0</spring_reference>
            <spring_stiffness>0</spring_stiffness>
          </dynamics>
          <use_parent_model_frame>1</use_parent_model_frame>
        </axis>
      </joint>
      <link name='left_wrist_3_link'>
        <pose frame=''>1.10929 0.13335 0.76147 -1.5708 0 1.5708</pose>
        <inertial>
          <pose frame=''>-0.000152 -0.004169 -0.09596 0 -0 0</pose>
          <mass>0.990094</mass>
          <inertia>
            <ixx>0.00425431</ixx>
            <ixy>6.65278e-07</ixy>
            <ixz>-1.49586e-05</ixz>
            <iyy>0.00411121</iyy>
            <iyz>0.000122735</iyz>
            <izz>0.000899307</izz>
          </inertia>
        </inertial>
        <collision name='left_wrist_3_link_collision'>
          <pose frame=''>0 0 0 0 -0 0</pose>
          <geometry>
            <mesh>
              <scale>1 1 1</scale>
              <uri>/home/jeff/movo_ws/src/kinova-movo/movo_common/movo_description/meshes/manipulation/jaco/collision/kinova_actuator_gearing.stl</uri>
            </mesh>
          </geometry>
          <surface>
            <contact>
              <ode>
                <kp>1e+06</kp>
                <kd>100</kd>
                <max_vel>100</max_vel>
                <min_depth>0.001</min_depth>
              </ode>
            </contact>
            <friction>
              <ode>
                <mu>1</mu>
                <mu2>1</mu2>
              </ode>
              <torsional>
                <ode/>
              </torsional>
            </friction>
            <bounce/>
          </surface>
          <max_contacts>10</max_contacts>
        </collision>
        <collision name='left_wrist_3_link_fixed_joint_lump__left_gripper_base_link_collision_1'>
          <pose frame=''>-0 0 0 0 -0 0</pose>
          <geometry>
            <mesh>
              <scale>1 1 1</scale>
              <uri>/home/jeff/movo_ws/src/kinova-movo/movo_common/movo_description/meshes/manipulation/kinova_grippers/collision/kg3_base_link.stl</uri>
            </mesh>
          </geometry>
          <surface>
            <contact>
              <ode>
                <kp>1e+06</kp>
                <kd>1</kd>
                <max_vel>0</max_vel>
                <min_depth>0.0001</min_depth>
              </ode>
            </contact>
            <friction>
              <ode>
                <mu>0.8</mu>
                <mu2>0.8</mu2>
              </ode>
              <torsional>
                <ode/>
              </torsional>
            </friction>
            <bounce/>
          </surface>
          <max_contacts>10</max_contacts>
        </collision>
        <visual name='left_wrist_3_link_visual'>
          <pose frame=''>0 0 0 0 -0 0</pose>
          <geometry>
            <mesh>
              <scale>1 1 1</scale>
              <uri>/home/jeff/movo_ws/src/kinova-movo/movo_common/movo_description/meshes/manipulation/jaco/visual/kinova_actuator_gearing.dae</uri>
            </mesh>
          </geometry>
          <material>
            <script>
              <uri>__default__</uri>
              <name>__default__</name>
            </script>
          </material>
        </visual>
        <visual name='left_wrist_3_link_fixed_joint_lump__left_gripper_base_link_visual_1'>
          <pose frame=''>-0 0 0 0 -0 0</pose>
          <geometry>
            <mesh>
              <scale>1 1 1</scale>
              <uri>/home/jeff/movo_ws/src/kinova-movo/movo_common/movo_description/meshes/manipulation/kinova_grippers/visual/kg3_base_link.dae</uri>
            </mesh>
          </geometry>
          <material>
            <script>
              <uri>__default__</uri>
              <name>__default__</name>
            </script>
          </material>
        </visual>
        <velocity_decay/>
        <gravity>1</gravity>
        <velocity_decay/>
        <self_collide>0</self_collide>
        <kinematic>0</kinematic>
      </link>
      <joint name='left_wrist_3_joint' type='revolute'>
        <child>left_wrist_3_link</child>
        <parent>left_wrist_spherical_2_link</parent>
        <axis>
          <xyz>-1 0 0</xyz>
          <limit>
            <lower>-3.14159</lower>
            <upper>3.14159</upper>
            <effort>60000.8</effort>
            <velocity>0.921534</velocity>
          </limit>
          <dynamics>
            <damping>0.01</damping>
            <friction>0</friction>
            <spring_reference>0</spring_reference>
            <spring_stiffness>0</spring_stiffness>
          </dynamics>
          <use_parent_model_frame>1</use_parent_model_frame>
        </axis>
      </joint>
      <link name='left_gripper_finger1_knuckle_link'>
        <pose frame=''>1.22393 0.130555 0.730152 3.08956 -1.39126 -1.62279</pose>
        <inertial>
          <pose frame=''>-0.028253 -0.032416 0 0 -0 0</pose>
          <mass>0.021817</mass>
          <inertia>
            <ixx>9.39482e-06</ixx>
            <ixy>-1.3461e-06</ixy>
            <ixz>0</ixz>
            <iyy>4.07539e-06</iyy>
            <iyz>0</iyz>
            <izz>1.14702e-05</izz>
          </inertia>
        </inertial>
        <collision name='left_gripper_finger1_knuckle_link_collision'>
          <pose frame=''>0 0 0 0 -0 0</pose>
          <geometry>
            <mesh>
              <scale>1 1 1</scale>
              <uri>/home/jeff/movo_ws/src/kinova-movo/movo_common/movo_description/meshes/manipulation/kinova_grippers/collision/finger_knuckle.stl</uri>
            </mesh>
          </geometry>
          <surface>
            <contact>
              <ode>
                <kp>1e+06</kp>
                <kd>1</kd>
                <max_vel>0</max_vel>
                <min_depth>0.0001</min_depth>
              </ode>
            </contact>
            <friction>
              <ode>
                <mu>0.8</mu>
                <mu2>0.8</mu2>
              </ode>
              <torsional>
                <ode/>
              </torsional>
            </friction>
            <bounce/>
          </surface>
          <max_contacts>10</max_contacts>
        </collision>
        <collision name='left_gripper_finger1_knuckle_link_fixed_joint_lump__left_gripper_finger1_finger_tip_link_collision_1'>
          <pose frame=''>-0.024598 -0.036051 0 0 -0 0</pose>
          <geometry>
            <mesh>
              <scale>1 1 1</scale>
              <uri>/home/jeff/movo_ws/src/kinova-movo/movo_common/movo_description/meshes/manipulation/kinova_grippers/collision/finger_tip.stl</uri>
            </mesh>
          </geometry>
          <surface>
            <contact>
              <ode>
                <kp>1e+06</kp>
                <kd>1</kd>
                <max_vel>0</max_vel>
                <min_depth>0.0001</min_depth>
              </ode>
            </contact>
            <friction>
              <ode>
                <mu>0.8</mu>
                <mu2>0.8</mu2>
              </ode>
              <torsional>
                <ode/>
              </torsional>
            </friction>
            <bounce/>
          </surface>
          <max_contacts>10</max_contacts>
        </collision>
        <visual name='left_gripper_finger1_knuckle_link_visual'>
          <pose frame=''>0 0 0 0 -0 0</pose>
          <geometry>
            <mesh>
              <scale>1 1 1</scale>
              <uri>/home/jeff/movo_ws/src/kinova-movo/movo_common/movo_description/meshes/manipulation/kinova_grippers/visual/finger_knuckle.dae</uri>
            </mesh>
          </geometry>
          <material>
            <script>
              <uri>__default__</uri>
              <name>__default__</name>
            </script>
          </material>
        </visual>
        <visual name='left_gripper_finger1_knuckle_link_fixed_joint_lump__left_gripper_finger1_finger_tip_link_visual_1'>
          <pose frame=''>-0.024598 -0.036051 0 0 -0 0</pose>
          <geometry>
            <mesh>
              <scale>1 1 1</scale>
              <uri>/home/jeff/movo_ws/src/kinova-movo/movo_common/movo_description/meshes/manipulation/kinova_grippers/visual/finger_tip.dae</uri>
            </mesh>
          </geometry>
          <material>
            <script>
              <uri>__default__</uri>
              <name>__default__</name>
            </script>
          </material>
        </visual>
        <velocity_decay/>
        <gravity>1</gravity>
        <velocity_decay/>
        <self_collide>0</self_collide>
        <kinematic>0</kinematic>
      </link>
      <joint name='left_gripper_finger1_joint' type='revolute'>
        <child>left_gripper_finger1_knuckle_link</child>
        <parent>left_wrist_3_link</parent>
        <axis>
          <xyz>-0.103009 -0.978563 -0.178336</xyz>
          <limit>
            <lower>0</lower>
            <upper>0.986111</upper>
            <effort>3</effort>
            <velocity>1</velocity>
          </limit>
          <dynamics>
            <spring_reference>0</spring_reference>
            <spring_stiffness>0</spring_stiffness>
          </dynamics>
          <use_parent_model_frame>1</use_parent_model_frame>
        </axis>
      </joint>
      <link name='left_gripper_finger2_knuckle_link'>
        <pose frame=''>1.224 0.155639 0.788723 3.14159 1.38609 -1.5708</pose>
        <inertial>
          <pose frame=''>-0.028253 -0.032416 0 0 -0 0</pose>
          <mass>0.021817</mass>
          <inertia>
            <ixx>9.39482e-06</ixx>
            <ixy>-1.3461e-06</ixy>
            <ixz>0</ixz>
            <iyy>4.07539e-06</iyy>
            <iyz>0</iyz>
            <izz>1.14702e-05</izz>
          </inertia>
        </inertial>
        <collision name='left_gripper_finger2_knuckle_link_collision'>
          <pose frame=''>0 0 0 0 -0 0</pose>
          <geometry>
            <mesh>
              <scale>1 1 1</scale>
              <uri>/home/jeff/movo_ws/src/kinova-movo/movo_common/movo_description/meshes/manipulation/kinova_grippers/collision/finger_knuckle.stl</uri>
            </mesh>
          </geometry>
          <surface>
            <contact>
              <ode>
                <kp>1e+06</kp>
                <kd>1</kd>
                <max_vel>0</max_vel>
                <min_depth>0.0001</min_depth>
              </ode>
            </contact>
            <friction>
              <ode>
                <mu>0.8</mu>
                <mu2>0.8</mu2>
              </ode>
              <torsional>
                <ode/>
              </torsional>
            </friction>
            <bounce/>
          </surface>
          <max_contacts>10</max_contacts>
        </collision>
        <collision name='left_gripper_finger2_knuckle_link_fixed_joint_lump__left_gripper_finger2_finger_tip_link_collision_1'>
          <pose frame=''>-0.024598 -0.036051 0 0 -0 0</pose>
          <geometry>
            <mesh>
              <scale>1 1 1</scale>
              <uri>/home/jeff/movo_ws/src/kinova-movo/movo_common/movo_description/meshes/manipulation/kinova_grippers/collision/finger_tip.stl</uri>
            </mesh>
          </geometry>
          <surface>
            <contact>
              <ode>
                <kp>1e+06</kp>
                <kd>1</kd>
                <max_vel>0</max_vel>
                <min_depth>0.0001</min_depth>
              </ode>
            </contact>
            <friction>
              <ode>
                <mu>0.8</mu>
                <mu2>0.8</mu2>
              </ode>
              <torsional>
                <ode/>
              </torsional>
            </friction>
            <bounce/>
          </surface>
          <max_contacts>10</max_contacts>
        </collision>
        <visual name='left_gripper_finger2_knuckle_link_visual'>
          <pose frame=''>0 0 0 0 -0 0</pose>
          <geometry>
            <mesh>
              <scale>1 1 1</scale>
              <uri>/home/jeff/movo_ws/src/kinova-movo/movo_common/movo_description/meshes/manipulation/kinova_grippers/visual/finger_knuckle.dae</uri>
            </mesh>
          </geometry>
          <material>
            <script>
              <uri>__default__</uri>
              <name>__default__</name>
            </script>
          </material>
        </visual>
        <visual name='left_gripper_finger2_knuckle_link_fixed_joint_lump__left_gripper_finger2_finger_tip_link_visual_1'>
          <pose frame=''>-0.024598 -0.036051 0 0 -0 0</pose>
          <geometry>
            <mesh>
              <scale>1 1 1</scale>
              <uri>/home/jeff/movo_ws/src/kinova-movo/movo_common/movo_description/meshes/manipulation/kinova_grippers/visual/finger_tip.dae</uri>
            </mesh>
          </geometry>
          <material>
            <script>
              <uri>__default__</uri>
              <name>__default__</name>
            </script>
          </material>
        </visual>
        <velocity_decay/>
        <gravity>1</gravity>
        <velocity_decay/>
        <self_collide>0</self_collide>
        <kinematic>0</kinematic>
      </link>
      <joint name='left_gripper_finger2_joint' type='revolute'>
        <child>left_gripper_finger2_knuckle_link</child>
        <parent>left_wrist_3_link</parent>
        <axis>
          <xyz>0 0.982991 -0.183655</xyz>
          <limit>
            <lower>0</lower>
            <upper>0.986111</upper>
            <effort>3</effort>
            <velocity>1</velocity>
          </limit>
          <dynamics>
            <spring_reference>0</spring_reference>
            <spring_stiffness>0</spring_stiffness>
          </dynamics>
          <use_parent_model_frame>1</use_parent_model_frame>
        </axis>
      </joint>
      <link name='left_gripper_finger3_knuckle_link'>
        <pose frame=''>1.22402 0.111066 0.788693 0 1.3861 1.5708</pose>
        <inertial>
          <pose frame=''>-0.028253 -0.032416 0 0 -0 0</pose>
          <mass>0.021817</mass>
          <inertia>
            <ixx>9.39482e-06</ixx>
            <ixy>-1.3461e-06</ixy>
            <ixz>0</ixz>
            <iyy>4.07539e-06</iyy>
            <iyz>0</iyz>
            <izz>1.14702e-05</izz>
          </inertia>
        </inertial>
        <collision name='left_gripper_finger3_knuckle_link_collision'>
          <pose frame=''>0 0 0 0 -0 0</pose>
          <geometry>
            <mesh>
              <scale>1 1 1</scale>
              <uri>/home/jeff/movo_ws/src/kinova-movo/movo_common/movo_description/meshes/manipulation/kinova_grippers/collision/finger_knuckle.stl</uri>
            </mesh>
          </geometry>
          <surface>
            <contact>
              <ode>
                <kp>1e+06</kp>
                <kd>1</kd>
                <max_vel>0</max_vel>
                <min_depth>0.0001</min_depth>
              </ode>
            </contact>
            <friction>
              <ode>
                <mu>0.8</mu>
                <mu2>0.8</mu2>
              </ode>
              <torsional>
                <ode/>
              </torsional>
            </friction>
            <bounce/>
          </surface>
          <max_contacts>10</max_contacts>
        </collision>
        <collision name='left_gripper_finger3_knuckle_link_fixed_joint_lump__left_gripper_finger3_finger_tip_link_collision_1'>
          <pose frame=''>-0.024598 -0.036051 0 0 -0 0</pose>
          <geometry>
            <mesh>
              <scale>1 1 1</scale>
              <uri>/home/jeff/movo_ws/src/kinova-movo/movo_common/movo_description/meshes/manipulation/kinova_grippers/collision/finger_tip.stl</uri>
            </mesh>
          </geometry>
          <surface>
            <contact>
              <ode>
                <kp>1e+06</kp>
                <kd>1</kd>
                <max_vel>0</max_vel>
                <min_depth>0.0001</min_depth>
              </ode>
            </contact>
            <friction>
              <ode>
                <mu>0.8</mu>
                <mu2>0.8</mu2>
              </ode>
              <torsional>
                <ode/>
              </torsional>
            </friction>
            <bounce/>
          </surface>
          <max_contacts>10</max_contacts>
        </collision>
        <visual name='left_gripper_finger3_knuckle_link_visual'>
          <pose frame=''>0 0 0 0 -0 0</pose>
          <geometry>
            <mesh>
              <scale>1 1 1</scale>
              <uri>/home/jeff/movo_ws/src/kinova-movo/movo_common/movo_description/meshes/manipulation/kinova_grippers/visual/finger_knuckle.dae</uri>
            </mesh>
          </geometry>
          <material>
            <script>
              <uri>__default__</uri>
              <name>__default__</name>
            </script>
          </material>
        </visual>
        <visual name='left_gripper_finger3_knuckle_link_fixed_joint_lump__left_gripper_finger3_finger_tip_link_visual_1'>
          <pose frame=''>-0.024598 -0.036051 0 0 -0 0</pose>
          <geometry>
            <mesh>
              <scale>1 1 1</scale>
              <uri>/home/jeff/movo_ws/src/kinova-movo/movo_common/movo_description/meshes/manipulation/kinova_grippers/visual/finger_tip.dae</uri>
            </mesh>
          </geometry>
          <material>
            <script>
              <uri>__default__</uri>
              <name>__default__</name>
            </script>
          </material>
        </visual>
        <velocity_decay/>
        <gravity>1</gravity>
        <velocity_decay/>
        <self_collide>0</self_collide>
        <kinematic>0</kinematic>
      </link>
      <joint name='left_gripper_finger3_joint' type='revolute'>
        <child>left_gripper_finger3_knuckle_link</child>
        <parent>left_wrist_3_link</parent>
        <axis>
          <xyz>0 0.982992 0.183648</xyz>
          <limit>
            <lower>0</lower>
            <upper>0.986111</upper>
            <effort>3</effort>
            <velocity>1</velocity>
          </limit>
          <dynamics>
            <spring_reference>0</spring_reference>
            <spring_stiffness>0</spring_stiffness>
          </dynamics>
          <use_parent_model_frame>1</use_parent_model_frame>
        </axis>
      </joint>
      <link name='pan_link'>
        <pose frame=''>0.27449 0 0.870315 3.14159 -0 0</pose>
        <inertial>
          <pose frame=''>-3.6e-05 0.021015 -0.052191 0 -0 0</pose>
          <mass>0.470548</mass>
          <inertia>
            <ixx>0.000957</ixx>
            <ixy>0</ixy>
            <ixz>0</ixz>
            <iyy>0.000805</iyy>
            <iyz>-0.000328</iyz>
            <izz>0.000353</izz>
          </inertia>
        </inertial>
        <collision name='pan_link_collision'>
          <pose frame=''>0 0 0 0 -0 0</pose>
          <geometry>
            <mesh>
              <scale>1 1 1</scale>
              <uri>/home/jeff/movo_ws/src/kinova-movo/movo_common/movo_description/meshes/pan_tilt/collision/pan_link.stl</uri>
            </mesh>
          </geometry>
          <max_contacts>10</max_contacts>
          <surface>
            <contact>
              <ode/>
            </contact>
            <bounce/>
            <friction>
              <torsional>
                <ode/>
              </torsional>
              <ode/>
            </friction>
          </surface>
        </collision>
        <visual name='pan_link_visual'>
          <pose frame=''>0 0 0 0 -0 0</pose>
          <geometry>
            <mesh>
              <scale>1 1 1</scale>
              <uri>/home/jeff/movo_ws/src/kinova-movo/movo_common/movo_description/meshes/pan_tilt/visual/pan_link.dae</uri>
            </mesh>
          </geometry>
        </visual>
        <self_collide>0</self_collide>
        <kinematic>0</kinematic>
      </link>
      <joint name='pan_joint' type='revolute'>
        <child>pan_link</child>
        <parent>linear_actuator_link</parent>
        <axis>
          <xyz>0 -3e-06 -1</xyz>
          <limit>
            <lower>-1.5708</lower>
            <upper>1.5708</upper>
            <effort>7</effort>
            <velocity>0.907571</velocity>
          </limit>
          <dynamics>
            <spring_reference>0</spring_reference>
            <spring_stiffness>0</spring_stiffness>
          </dynamics>
          <use_parent_model_frame>1</use_parent_model_frame>
        </axis>
      </joint>
      <link name='tilt_link'>
        <pose frame=''>0.27449 -0.026 0.961065 0.463649 -1.57079 1.10715</pose>
        <inertial>
          <pose frame=''>0.013478 -0.00669 -0.040467 0 -0 0</pose>
          <mass>1.83451</mass>
          <inertia>
            <ixx>0.00777963</ixx>
            <ixy>-5.63296e-05</ixy>
            <ixz>-0.000358143</ixz>
            <iyy>0.00239627</iyy>
            <iyz>-0.00019448</iyz>
            <izz>0.00257745</izz>
          </inertia>
        </inertial>
        <collision name='tilt_link_collision'>
          <pose frame=''>0 0 0 0 -0 0</pose>
          <geometry>
            <mesh>
              <scale>1 1 1</scale>
              <uri>/home/jeff/movo_ws/src/kinova-movo/movo_common/movo_description/meshes/pan_tilt/collision/tilt_link.stl</uri>
            </mesh>
          </geometry>
          <max_contacts>10</max_contacts>
          <surface>
            <contact>
              <ode/>
            </contact>
            <bounce/>
            <friction>
              <torsional>
                <ode/>
              </torsional>
              <ode/>
            </friction>
          </surface>
        </collision>
        <collision name='tilt_link_fixed_joint_lump__kinect2_link_collision_1'>
          <pose frame=''>0.05825 -0.010588 -0.026 -1.57079 -0 -1.57079</pose>
          <geometry>
            <mesh>
              <scale>1 1 1</scale>
              <uri>/home/jeff/movo_ws/src/kinova-movo/movo_common/movo_description/meshes/sensors/collision/kinect_one_collision.stl</uri>
            </mesh>
          </geometry>
          <max_contacts>10</max_contacts>
          <surface>
            <contact>
              <ode/>
            </contact>
            <bounce/>
            <friction>
              <torsional>
                <ode/>
              </torsional>
              <ode/>
            </friction>
          </surface>
        </collision>
        <visual name='tilt_link_visual'>
          <pose frame=''>0 0 0 0 -0 0</pose>
          <geometry>
            <mesh>
              <scale>1 1 1</scale>
              <uri>/home/jeff/movo_ws/src/kinova-movo/movo_common/movo_description/meshes/pan_tilt/visual/tilt_link.dae</uri>
            </mesh>
          </geometry>
        </visual>
        <visual name='tilt_link_fixed_joint_lump__kinect2_link_visual_1'>
          <pose frame=''>0.05825 -0.010588 -0.026 -1.57079 -0 -1.57079</pose>
          <geometry>
            <mesh>
              <scale>1 1 1</scale>
              <uri>/home/jeff/movo_ws/src/kinova-movo/movo_common/movo_description/meshes/sensors/visual/kinect_one.dae</uri>
            </mesh>
          </geometry>
        </visual>
        <gravity>1</gravity>
        <velocity_decay/>
        <sensor name='kinect2_ir_sensor' type='depth'>
          <always_on>1</always_on>
          <update_rate>30</update_rate>
          <camera name='__default__'>
            <horizontal_fov>1.22173</horizontal_fov>
            <image>
              <format>L8</format>
              <width>512</width>
              <height>424</height>
            </image>
            <clip>
              <near>0.01</near>
              <far>100</far>
            </clip>
          </camera>
          <plugin name='kinect2_ir_link_controller' filename='libgazebo_ros_openni_kinect.so'>
            <baseline>0.2</baseline>
            <alwaysOn>true</alwaysOn>
            <updateRate>1.0</updateRate>
            <cameraName>kinect2/sd/image_ir</cameraName>
            <imageTopicName>/kinect2/sd/image_ir</imageTopicName>
            <cameraInfoTopicName>/kinect2/sd/camera_info</cameraInfoTopicName>
            <depthImageTopicName>/kinect2/sd/image_depth</depthImageTopicName>
            <depthImageCameraInfoTopicName>/kinect2/sd/depth/camera_info</depthImageCameraInfoTopicName>
            <pointCloudTopicName>/kinect2/sd/points</pointCloudTopicName>
            <frameName>kinect2_ir_optical_frame</frameName>
            <pointCloudCutoff>0.1</pointCloudCutoff>
            <pointCloudCutoffMax>12.0</pointCloudCutoffMax>
            <distortionK1>0.0</distortionK1>
            <distortionK2>0.0</distortionK2>
            <distortionK3>0.0</distortionK3>
            <distortionT1>0.0</distortionT1>
            <distortionT2>0.0</distortionT2>
            <CxPrime>0</CxPrime>
            <Cx>0</Cx>
            <Cy>0</Cy>
            <focalLength>0</focalLength>
            <hackBaseline>0</hackBaseline>
            <robotNamespace>/</robotNamespace>
          </plugin>
          <pose frame=''>0.10026 -0.035087 0.00725 -1.57079 -0 -1.57079</pose>
        </sensor>
        <self_collide>0</self_collide>
        <kinematic>0</kinematic>
      </link>
      <joint name='tilt_joint' type='revolute'>
        <child>tilt_link</child>
        <parent>pan_link</parent>
        <axis>
          <xyz>1e-06 -1 3e-06</xyz>
          <limit>
            <lower>-1.5708</lower>
            <upper>1.5708</upper>
            <effort>7</effort>
            <velocity>0.907571</velocity>
          </limit>
          <dynamics>
            <spring_reference>0</spring_reference>
            <spring_stiffness>0</spring_stiffness>
          </dynamics>
          <use_parent_model_frame>1</use_parent_model_frame>
        </axis>
      </joint>
      <link name='right_shoulder_link'>
        <pose frame=''>0.165745 -0.13335 0.75007 -1.5708 0 1.5708</pose>
        <inertial>
          <pose frame=''>1.8e-05 -0.004667 -0.060609 0 -0 0</pose>
          <mass>0.824524</mass>
          <inertia>
            <ixx>0.002561</ixx>
            <ixy>0</ixy>
            <ixz>1e-06</ixz>
            <iyy>0.002653</iyy>
            <iyz>0.000212</iyz>
            <izz>0.000524</izz>
          </inertia>
        </inertial>
        <collision name='right_shoulder_link_collision'>
          <pose frame=''>0 0 0 0 -0 0</pose>
          <geometry>
            <mesh>
              <scale>1 1 1</scale>
              <uri>/home/jeff/movo_ws/src/kinova-movo/movo_common/movo_description/meshes/manipulation/jaco/collision/shoulder_7dof.stl</uri>
            </mesh>
          </geometry>
          <surface>
            <contact>
              <ode>
                <kp>1e+06</kp>
                <kd>100</kd>
                <max_vel>100</max_vel>
                <min_depth>0.001</min_depth>
              </ode>
            </contact>
            <friction>
              <ode>
                <mu>1</mu>
                <mu2>1</mu2>
              </ode>
              <torsional>
                <ode/>
              </torsional>
            </friction>
            <bounce/>
          </surface>
          <max_contacts>10</max_contacts>
        </collision>
        <visual name='right_shoulder_link_visual'>
          <pose frame=''>0 0 0 0 -0 0</pose>
          <geometry>
            <mesh>
              <scale>1 1 1</scale>
              <uri>/home/jeff/movo_ws/src/kinova-movo/movo_common/movo_description/meshes/manipulation/jaco/visual/shoulder_7dof.dae</uri>
            </mesh>
          </geometry>
          <material>
            <script>
              <uri>__default__</uri>
              <name>__default__</name>
            </script>
          </material>
        </visual>
        <gravity>1</gravity>
        <velocity_decay/>
        <self_collide>0</self_collide>
        <kinematic>0</kinematic>
      </link>
      <joint name='right_shoulder_pan_joint' type='revolute'>
        <child>right_shoulder_link</child>
        <parent>linear_actuator_link</parent>
        <axis>
          <xyz>-1 0 0</xyz>
          <limit>
            <lower>-3.14159</lower>
            <upper>3.14159</upper>
            <effort>18000</effort>
            <velocity>0.69115</velocity>
          </limit>
          <dynamics>
            <damping>0.01</damping>
            <friction>0</friction>
            <spring_reference>0</spring_reference>
            <spring_stiffness>0</spring_stiffness>
          </dynamics>
          <use_parent_model_frame>1</use_parent_model_frame>
        </axis>
      </joint>
      <link name='right_arm_half_1_link'>
        <pose frame=''>0.284495 -0.13335 0.75007 0 -0 1.5708</pose>
        <inertial>
          <pose frame=''>0 -0.103563 0 0 -0 0</pose>
          <mass>0.8447</mass>
          <inertia>
            <ixx>0.000435</ixx>
            <ixy>2e-06</ixy>
            <ixz>0.000231</ixz>
            <iyy>0.034947</iyy>
            <iyz>0</iyz>
            <izz>0.035198</izz>
          </inertia>
        </inertial>
        <collision name='right_arm_half_1_link_collision'>
          <pose frame=''>0 0 0 0 -0 0</pose>
          <geometry>
            <mesh>
              <scale>1 1 1</scale>
              <uri>/home/jeff/movo_ws/src/kinova-movo/movo_common/movo_description/meshes/manipulation/jaco/collision/arm_half_1.stl</uri>
            </mesh>
          </geometry>
          <surface>
            <contact>
              <ode>
                <kp>1e+06</kp>
                <kd>100</kd>
                <max_vel>100</max_vel>
                <min_depth>0.001</min_depth>
              </ode>
            </contact>
            <friction>
              <ode>
                <mu>1</mu>
                <mu2>1</mu2>
              </ode>
              <torsional>
                <ode/>
              </torsional>
            </friction>
            <bounce/>
          </surface>
          <max_contacts>10</max_contacts>
        </collision>
        <visual name='right_arm_half_1_link_visual'>
          <pose frame=''>0 0 0 0 -0 0</pose>
          <geometry>
            <mesh>
              <scale>1 1 1</scale>
              <uri>/home/jeff/movo_ws/src/kinova-movo/movo_common/movo_description/meshes/manipulation/jaco/visual/arm_half_1.dae</uri>
            </mesh>
          </geometry>
          <material>
            <script>
              <uri>__default__</uri>
              <name>__default__</name>
            </script>
          </material>
        </visual>
        <gravity>1</gravity>
        <velocity_decay/>
        <self_collide>0</self_collide>
        <kinematic>0</kinematic>
      </link>
      <joint name='right_shoulder_lift_joint' type='revolute'>
        <child>right_arm_half_1_link</child>
        <parent>right_shoulder_link</parent>
        <axis>
          <xyz>0 0 1</xyz>
          <limit>
            <lower>-2.238</lower>
            <upper>2.238</upper>
            <effort>30000.5</effort>
            <velocity>0.69115</velocity>
          </limit>
          <dynamics>
            <damping>0.01</damping>
            <friction>0</friction>
            <spring_reference>0</spring_reference>
            <spring_stiffness>0</spring_stiffness>
          </dynamics>
          <use_parent_model_frame>1</use_parent_model_frame>
        </axis>
      </joint>
      <link name='right_arm_half_2_link'>
        <pose frame=''>0.489495 -0.13335 0.75007 -1.5708 0 1.5708</pose>
        <inertial>
          <pose frame=''>0 0 -0.102245 0 -0 0</pose>
          <mass>0.8447</mass>
          <inertia>
            <ixx>0.000435</ixx>
            <ixy>2e-06</ixy>
            <ixz>0.000231</ixz>
            <iyy>0.034947</iyy>
            <iyz>0</iyz>
            <izz>0.035198</izz>
          </inertia>
        </inertial>
        <collision name='right_arm_half_2_link_collision'>
          <pose frame=''>0 0 0 0 -0 0</pose>
          <geometry>
            <mesh>
              <scale>1 1 1</scale>
              <uri>/home/jeff/movo_ws/src/kinova-movo/movo_common/movo_description/meshes/manipulation/jaco/collision/arm_half_2.stl</uri>
            </mesh>
          </geometry>
          <surface>
            <contact>
              <ode>
                <kp>1e+06</kp>
                <kd>100</kd>
                <max_vel>100</max_vel>
                <min_depth>0.001</min_depth>
              </ode>
            </contact>
            <friction>
              <ode>
                <mu>1</mu>
                <mu2>1</mu2>
              </ode>
              <torsional>
                <ode/>
              </torsional>
            </friction>
            <bounce/>
          </surface>
          <max_contacts>10</max_contacts>
        </collision>
        <visual name='right_arm_half_2_link_visual'>
          <pose frame=''>0 0 0 0 -0 0</pose>
          <geometry>
            <mesh>
              <scale>1 1 1</scale>
              <uri>/home/jeff/movo_ws/src/kinova-movo/movo_common/movo_description/meshes/manipulation/jaco/visual/arm_half_2.dae</uri>
            </mesh>
          </geometry>
          <material>
            <script>
              <uri>__default__</uri>
              <name>__default__</name>
            </script>
          </material>
        </visual>
        <gravity>1</gravity>
        <velocity_decay/>
        <self_collide>0</self_collide>
        <kinematic>0</kinematic>
      </link>
      <joint name='right_arm_half_joint' type='revolute'>
        <child>right_arm_half_2_link</child>
        <parent>right_arm_half_1_link</parent>
        <axis>
          <xyz>-1 0 0</xyz>
          <limit>
            <lower>-3.14159</lower>
            <upper>3.14159</upper>
            <effort>30000.5</effort>
            <velocity>0.69115</velocity>
          </limit>
          <dynamics>
            <damping>0.01</damping>
            <friction>0</friction>
            <spring_reference>0</spring_reference>
            <spring_stiffness>0</spring_stiffness>
          </dynamics>
          <use_parent_model_frame>1</use_parent_model_frame>
        </axis>
      </joint>
      <link name='right_forearm_link'>
        <pose frame=''>0.694495 -0.13335 0.75007 -3.14159 -0 1.5708</pose>
        <inertial>
          <pose frame=''>0 0.081 -0.0086 0 -0 0</pose>
          <mass>0.674254</mass>
          <inertia>
            <ixx>0.005453</ixx>
            <ixy>3e-06</ixy>
            <ixz>0</ixz>
            <iyy>0.000305</iyy>
            <iyz>8.7e-05</iyz>
            <izz>0.005578</izz>
          </inertia>
        </inertial>
        <collision name='right_forearm_link_collision'>
          <pose frame=''>0 0 0 0 -0 0</pose>
          <geometry>
            <mesh>
              <scale>1 1 1</scale>
              <uri>/home/jeff/movo_ws/src/kinova-movo/movo_common/movo_description/meshes/manipulation/jaco/collision/forearm_7dof.stl</uri>
            </mesh>
          </geometry>
          <max_contacts>10</max_contacts>
          <surface>
            <contact>
              <ode/>
            </contact>
            <bounce/>
            <friction>
              <torsional>
                <ode/>
              </torsional>
              <ode/>
            </friction>
          </surface>
        </collision>
        <visual name='right_forearm_link_visual'>
          <pose frame=''>0 0 0 0 -0 0</pose>
          <geometry>
            <mesh>
              <scale>1 1 1</scale>
              <uri>/home/jeff/movo_ws/src/kinova-movo/movo_common/movo_description/meshes/manipulation/jaco/visual/forearm_7dof.dae</uri>
            </mesh>
          </geometry>
        </visual>
        <self_collide>0</self_collide>
        <kinematic>0</kinematic>
      </link>
      <joint name='right_elbow_joint' type='revolute'>
        <child>right_forearm_link</child>
        <parent>right_arm_half_2_link</parent>
        <axis>
          <xyz>0 0 -1</xyz>
          <limit>
            <lower>-2.809</lower>
            <upper>2.809</upper>
            <effort>18000</effort>
            <velocity>0.69115</velocity>
          </limit>
          <dynamics>
            <damping>0.01</damping>
            <friction>0</friction>
            <spring_reference>0</spring_reference>
            <spring_stiffness>0</spring_stiffness>
          </dynamics>
          <use_parent_model_frame>1</use_parent_model_frame>
        </axis>
      </joint>
      <link name='right_wrist_spherical_1_link'>
        <pose frame=''>0.901795 -0.13335 0.76147 1.5708 0 -1.5708</pose>
        <inertial>
          <pose frame=''>0 0.002885 -0.054193 0 -0 0</pose>
          <mass>0.463</mass>
          <inertia>
            <ixx>0.000392</ixx>
            <ixy>0</ixy>
            <ixz>0</ixz>
            <iyy>0.000347</iyy>
            <iyz>0.000101</iyz>
            <izz>0.000233</izz>
          </inertia>
        </inertial>
        <collision name='right_wrist_spherical_1_link_collision'>
          <pose frame=''>0 0 0 0 -0 0</pose>
          <geometry>
            <mesh>
              <scale>1 1 1</scale>
              <uri>/home/jeff/movo_ws/src/kinova-movo/movo_common/movo_description/meshes/manipulation/jaco/collision/wrist_spherical_1.stl</uri>
            </mesh>
          </geometry>
          <surface>
            <contact>
              <ode>
                <kp>1e+06</kp>
                <kd>100</kd>
                <max_vel>100</max_vel>
                <min_depth>0.001</min_depth>
              </ode>
            </contact>
            <friction>
              <ode>
                <mu>1</mu>
                <mu2>1</mu2>
              </ode>
              <torsional>
                <ode/>
              </torsional>
            </friction>
            <bounce/>
          </surface>
          <max_contacts>10</max_contacts>
        </collision>
        <visual name='right_wrist_spherical_1_link_visual'>
          <pose frame=''>0 0 0 0 -0 0</pose>
          <geometry>
            <mesh>
              <scale>1 1 1</scale>
              <uri>/home/jeff/movo_ws/src/kinova-movo/movo_common/movo_description/meshes/manipulation/jaco/visual/wrist_spherical_1.dae</uri>
            </mesh>
          </geometry>
          <material>
            <script>
              <uri>__default__</uri>
              <name>__default__</name>
            </script>
          </material>
        </visual>
        <gravity>1</gravity>
        <velocity_decay/>
        <self_collide>0</self_collide>
        <kinematic>0</kinematic>
      </link>
      <joint name='right_wrist_spherical_1_joint' type='revolute'>
        <child>right_wrist_spherical_1_link</child>
        <parent>right_forearm_link</parent>
        <axis>
          <xyz>-1 0 0</xyz>
          <limit>
            <lower>-3.14159</lower>
            <upper>3.14159</upper>
            <effort>60000.8</effort>
            <velocity>0.921534</velocity>
          </limit>
          <dynamics>
            <damping>0.01</damping>
            <friction>0</friction>
            <spring_reference>0</spring_reference>
            <spring_stiffness>0</spring_stiffness>
          </dynamics>
          <use_parent_model_frame>1</use_parent_model_frame>
        </axis>
      </joint>
      <link name='right_wrist_spherical_2_link'>
        <pose frame=''>1.00554 -0.13335 0.76147 -0 -0 -1.5708</pose>
        <inertial>
          <pose frame=''>0 0.049721 -0.002856 0 -0 0</pose>
          <mass>0.463</mass>
          <inertia>
            <ixx>0.000392</ixx>
            <ixy>0</ixy>
            <ixz>0</ixz>
            <iyy>0.000347</iyy>
            <iyz>0.000101</iyz>
            <izz>0.000233</izz>
          </inertia>
        </inertial>
        <collision name='right_wrist_spherical_2_link_collision'>
          <pose frame=''>0 0 0 0 -0 0</pose>
          <geometry>
            <mesh>
              <scale>1 1 1</scale>
              <uri>/home/jeff/movo_ws/src/kinova-movo/movo_common/movo_description/meshes/manipulation/jaco/collision/wrist_spherical_2.stl</uri>
            </mesh>
          </geometry>
          <surface>
            <contact>
              <ode>
                <kp>1e+06</kp>
                <kd>100</kd>
                <max_vel>100</max_vel>
                <min_depth>0.001</min_depth>
              </ode>
            </contact>
            <friction>
              <ode>
                <mu>1</mu>
                <mu2>1</mu2>
              </ode>
              <torsional>
                <ode/>
              </torsional>
            </friction>
            <bounce/>
          </surface>
          <max_contacts>10</max_contacts>
        </collision>
        <visual name='right_wrist_spherical_2_link_visual'>
          <pose frame=''>0 0 0 0 -0 0</pose>
          <geometry>
            <mesh>
              <scale>1 1 1</scale>
              <uri>/home/jeff/movo_ws/src/kinova-movo/movo_common/movo_description/meshes/manipulation/jaco/visual/wrist_spherical_2.dae</uri>
            </mesh>
          </geometry>
          <material>
            <script>
              <uri>__default__</uri>
              <name>__default__</name>
            </script>
          </material>
        </visual>
        <gravity>1</gravity>
        <velocity_decay/>
        <self_collide>0</self_collide>
        <kinematic>0</kinematic>
      </link>
      <joint name='right_wrist_spherical_2_joint' type='revolute'>
        <child>right_wrist_spherical_2_link</child>
        <parent>right_wrist_spherical_1_link</parent>
        <axis>
          <xyz>0 0 1</xyz>
          <limit>
            <lower>-2.78</lower>
            <upper>2.78</upper>
            <effort>60000.8</effort>
            <velocity>0.921534</velocity>
          </limit>
          <dynamics>
            <damping>0.01</damping>
            <friction>0</friction>
            <spring_reference>0</spring_reference>
            <spring_stiffness>0</spring_stiffness>
          </dynamics>
          <use_parent_model_frame>1</use_parent_model_frame>
        </axis>
      </joint>
      <link name='right_wrist_3_link'>
        <pose frame=''>1.10929 -0.13335 0.76147 -1.5708 0 1.5708</pose>
        <inertial>
          <pose frame=''>-0.000152 -0.004169 -0.09596 0 -0 0</pose>
          <mass>0.990094</mass>
          <inertia>
            <ixx>0.00425431</ixx>
            <ixy>6.65278e-07</ixy>
            <ixz>-1.49586e-05</ixz>
            <iyy>0.00411121</iyy>
            <iyz>0.000122735</iyz>
            <izz>0.000899307</izz>
          </inertia>
        </inertial>
        <collision name='right_wrist_3_link_collision'>
          <pose frame=''>0 0 0 0 -0 0</pose>
          <geometry>
            <mesh>
              <scale>1 1 1</scale>
              <uri>/home/jeff/movo_ws/src/kinova-movo/movo_common/movo_description/meshes/manipulation/jaco/collision/kinova_actuator_gearing.stl</uri>
            </mesh>
          </geometry>
          <surface>
            <contact>
              <ode>
                <kp>1e+06</kp>
                <kd>100</kd>
                <max_vel>100</max_vel>
                <min_depth>0.001</min_depth>
              </ode>
            </contact>
            <friction>
              <ode>
                <mu>1</mu>
                <mu2>1</mu2>
              </ode>
              <torsional>
                <ode/>
              </torsional>
            </friction>
            <bounce/>
          </surface>
          <max_contacts>10</max_contacts>
        </collision>
        <collision name='right_wrist_3_link_fixed_joint_lump__right_gripper_base_link_collision_1'>
          <pose frame=''>-0 0 0 0 -0 0</pose>
          <geometry>
            <mesh>
              <scale>1 1 1</scale>
              <uri>/home/jeff/movo_ws/src/kinova-movo/movo_common/movo_description/meshes/manipulation/kinova_grippers/collision/kg3_base_link.stl</uri>
            </mesh>
          </geometry>
          <surface>
            <contact>
              <ode>
                <kp>1e+06</kp>
                <kd>1</kd>
                <max_vel>0</max_vel>
                <min_depth>0.0001</min_depth>
              </ode>
            </contact>
            <friction>
              <ode>
                <mu>0.8</mu>
                <mu2>0.8</mu2>
              </ode>
              <torsional>
                <ode/>
              </torsional>
            </friction>
            <bounce/>
          </surface>
          <max_contacts>10</max_contacts>
        </collision>
        <visual name='right_wrist_3_link_visual'>
          <pose frame=''>0 0 0 0 -0 0</pose>
          <geometry>
            <mesh>
              <scale>1 1 1</scale>
              <uri>/home/jeff/movo_ws/src/kinova-movo/movo_common/movo_description/meshes/manipulation/jaco/visual/kinova_actuator_gearing.dae</uri>
            </mesh>
          </geometry>
          <material>
            <script>
              <uri>__default__</uri>
              <name>__default__</name>
            </script>
          </material>
        </visual>
        <visual name='right_wrist_3_link_fixed_joint_lump__right_gripper_base_link_visual_1'>
          <pose frame=''>-0 0 0 0 -0 0</pose>
          <geometry>
            <mesh>
              <scale>1 1 1</scale>
              <uri>/home/jeff/movo_ws/src/kinova-movo/movo_common/movo_description/meshes/manipulation/kinova_grippers/visual/kg3_base_link.dae</uri>
            </mesh>
          </geometry>
          <material>
            <script>
              <uri>__default__</uri>
              <name>__default__</name>
            </script>
          </material>
        </visual>
        <velocity_decay/>
        <gravity>1</gravity>
        <velocity_decay/>
        <self_collide>0</self_collide>
        <kinematic>0</kinematic>
      </link>
      <joint name='right_wrist_3_joint' type='revolute'>
        <child>right_wrist_3_link</child>
        <parent>right_wrist_spherical_2_link</parent>
        <axis>
          <xyz>-1 0 0</xyz>
          <limit>
            <lower>-3.14159</lower>
            <upper>3.14159</upper>
            <effort>60000.8</effort>
            <velocity>0.921534</velocity>
          </limit>
          <dynamics>
            <damping>0.01</damping>
            <friction>0</friction>
            <spring_reference>0</spring_reference>
            <spring_stiffness>0</spring_stiffness>
          </dynamics>
          <use_parent_model_frame>1</use_parent_model_frame>
        </axis>
      </joint>
      <link name='right_gripper_finger1_knuckle_link'>
        <pose frame=''>1.22393 -0.136145 0.730152 3.08956 -1.39126 -1.62279</pose>
        <inertial>
          <pose frame=''>-0.028253 -0.032416 0 0 -0 0</pose>
          <mass>0.021817</mass>
          <inertia>
            <ixx>9.39482e-06</ixx>
            <ixy>-1.3461e-06</ixy>
            <ixz>0</ixz>
            <iyy>4.07539e-06</iyy>
            <iyz>0</iyz>
            <izz>1.14702e-05</izz>
          </inertia>
        </inertial>
        <collision name='right_gripper_finger1_knuckle_link_collision'>
          <pose frame=''>0 0 0 0 -0 0</pose>
          <geometry>
            <mesh>
              <scale>1 1 1</scale>
              <uri>/home/jeff/movo_ws/src/kinova-movo/movo_common/movo_description/meshes/manipulation/kinova_grippers/collision/finger_knuckle.stl</uri>
            </mesh>
          </geometry>
          <surface>
            <contact>
              <ode>
                <kp>1e+06</kp>
                <kd>1</kd>
                <max_vel>0</max_vel>
                <min_depth>0.0001</min_depth>
              </ode>
            </contact>
            <friction>
              <ode>
                <mu>0.8</mu>
                <mu2>0.8</mu2>
              </ode>
              <torsional>
                <ode/>
              </torsional>
            </friction>
            <bounce/>
          </surface>
          <max_contacts>10</max_contacts>
        </collision>
        <collision name='right_gripper_finger1_knuckle_link_fixed_joint_lump__right_gripper_finger1_finger_tip_link_collision_1'>
          <pose frame=''>-0.024598 -0.036051 0 0 -0 0</pose>
          <geometry>
            <mesh>
              <scale>1 1 1</scale>
              <uri>/home/jeff/movo_ws/src/kinova-movo/movo_common/movo_description/meshes/manipulation/kinova_grippers/collision/finger_tip.stl</uri>
            </mesh>
          </geometry>
          <surface>
            <contact>
              <ode>
                <kp>1e+06</kp>
                <kd>1</kd>
                <max_vel>0</max_vel>
                <min_depth>0.0001</min_depth>
              </ode>
            </contact>
            <friction>
              <ode>
                <mu>0.8</mu>
                <mu2>0.8</mu2>
              </ode>
              <torsional>
                <ode/>
              </torsional>
            </friction>
            <bounce/>
          </surface>
          <max_contacts>10</max_contacts>
        </collision>
        <visual name='right_gripper_finger1_knuckle_link_visual'>
          <pose frame=''>0 0 0 0 -0 0</pose>
          <geometry>
            <mesh>
              <scale>1 1 1</scale>
              <uri>/home/jeff/movo_ws/src/kinova-movo/movo_common/movo_description/meshes/manipulation/kinova_grippers/visual/finger_knuckle.dae</uri>
            </mesh>
          </geometry>
          <material>
            <script>
              <uri>__default__</uri>
              <name>__default__</name>
            </script>
          </material>
        </visual>
        <visual name='right_gripper_finger1_knuckle_link_fixed_joint_lump__right_gripper_finger1_finger_tip_link_visual_1'>
          <pose frame=''>-0.024598 -0.036051 0 0 -0 0</pose>
          <geometry>
            <mesh>
              <scale>1 1 1</scale>
              <uri>/home/jeff/movo_ws/src/kinova-movo/movo_common/movo_description/meshes/manipulation/kinova_grippers/visual/finger_tip.dae</uri>
            </mesh>
          </geometry>
          <material>
            <script>
              <uri>__default__</uri>
              <name>__default__</name>
            </script>
          </material>
        </visual>
        <velocity_decay/>
        <gravity>1</gravity>
        <velocity_decay/>
        <self_collide>0</self_collide>
        <kinematic>0</kinematic>
      </link>
      <joint name='right_gripper_finger1_joint' type='revolute'>
        <child>right_gripper_finger1_knuckle_link</child>
        <parent>right_wrist_3_link</parent>
        <axis>
          <xyz>-0.103009 -0.978563 -0.178336</xyz>
          <limit>
            <lower>0</lower>
            <upper>0.986111</upper>
            <effort>3</effort>
            <velocity>1</velocity>
          </limit>
          <dynamics>
            <spring_reference>0</spring_reference>
            <spring_stiffness>0</spring_stiffness>
          </dynamics>
          <use_parent_model_frame>1</use_parent_model_frame>
        </axis>
      </joint>
      <link name='right_gripper_finger2_knuckle_link'>
        <pose frame=''>1.224 -0.111061 0.788723 3.14159 1.38609 -1.5708</pose>
        <inertial>
          <pose frame=''>-0.028253 -0.032416 0 0 -0 0</pose>
          <mass>0.021817</mass>
          <inertia>
            <ixx>9.39482e-06</ixx>
            <ixy>-1.3461e-06</ixy>
            <ixz>0</ixz>
            <iyy>4.07539e-06</iyy>
            <iyz>0</iyz>
            <izz>1.14702e-05</izz>
          </inertia>
        </inertial>
        <collision name='right_gripper_finger2_knuckle_link_collision'>
          <pose frame=''>0 0 0 0 -0 0</pose>
          <geometry>
            <mesh>
              <scale>1 1 1</scale>
              <uri>/home/jeff/movo_ws/src/kinova-movo/movo_common/movo_description/meshes/manipulation/kinova_grippers/collision/finger_knuckle.stl</uri>
            </mesh>
          </geometry>
          <surface>
            <contact>
              <ode>
                <kp>1e+06</kp>
                <kd>1</kd>
                <max_vel>0</max_vel>
                <min_depth>0.0001</min_depth>
              </ode>
            </contact>
            <friction>
              <ode>
                <mu>0.8</mu>
                <mu2>0.8</mu2>
              </ode>
              <torsional>
                <ode/>
              </torsional>
            </friction>
            <bounce/>
          </surface>
          <max_contacts>10</max_contacts>
        </collision>
        <collision name='right_gripper_finger2_knuckle_link_fixed_joint_lump__right_gripper_finger2_finger_tip_link_collision_1'>
          <pose frame=''>-0.024598 -0.036051 0 0 -0 0</pose>
          <geometry>
            <mesh>
              <scale>1 1 1</scale>
              <uri>/home/jeff/movo_ws/src/kinova-movo/movo_common/movo_description/meshes/manipulation/kinova_grippers/collision/finger_tip.stl</uri>
            </mesh>
          </geometry>
          <surface>
            <contact>
              <ode>
                <kp>1e+06</kp>
                <kd>1</kd>
                <max_vel>0</max_vel>
                <min_depth>0.0001</min_depth>
              </ode>
            </contact>
            <friction>
              <ode>
                <mu>0.8</mu>
                <mu2>0.8</mu2>
              </ode>
              <torsional>
                <ode/>
              </torsional>
            </friction>
            <bounce/>
          </surface>
          <max_contacts>10</max_contacts>
        </collision>
        <visual name='right_gripper_finger2_knuckle_link_visual'>
          <pose frame=''>0 0 0 0 -0 0</pose>
          <geometry>
            <mesh>
              <scale>1 1 1</scale>
              <uri>/home/jeff/movo_ws/src/kinova-movo/movo_common/movo_description/meshes/manipulation/kinova_grippers/visual/finger_knuckle.dae</uri>
            </mesh>
          </geometry>
          <material>
            <script>
              <uri>__default__</uri>
              <name>__default__</name>
            </script>
          </material>
        </visual>
        <visual name='right_gripper_finger2_knuckle_link_fixed_joint_lump__right_gripper_finger2_finger_tip_link_visual_1'>
          <pose frame=''>-0.024598 -0.036051 0 0 -0 0</pose>
          <geometry>
            <mesh>
              <scale>1 1 1</scale>
              <uri>/home/jeff/movo_ws/src/kinova-movo/movo_common/movo_description/meshes/manipulation/kinova_grippers/visual/finger_tip.dae</uri>
            </mesh>
          </geometry>
          <material>
            <script>
              <uri>__default__</uri>
              <name>__default__</name>
            </script>
          </material>
        </visual>
        <velocity_decay/>
        <gravity>1</gravity>
        <velocity_decay/>
        <self_collide>0</self_collide>
        <kinematic>0</kinematic>
      </link>
      <joint name='right_gripper_finger2_joint' type='revolute'>
        <child>right_gripper_finger2_knuckle_link</child>
        <parent>right_wrist_3_link</parent>
        <axis>
          <xyz>0 0.982991 -0.183655</xyz>
          <limit>
            <lower>0</lower>
            <upper>0.986111</upper>
            <effort>3</effort>
            <velocity>1</velocity>
          </limit>
          <dynamics>
            <spring_reference>0</spring_reference>
            <spring_stiffness>0</spring_stiffness>
          </dynamics>
          <use_parent_model_frame>1</use_parent_model_frame>
        </axis>
      </joint>
      <link name='right_gripper_finger3_knuckle_link'>
        <pose frame=''>1.22402 -0.155634 0.788693 0 1.3861 1.5708</pose>
        <inertial>
          <pose frame=''>-0.028253 -0.032416 0 0 -0 0</pose>
          <mass>0.021817</mass>
          <inertia>
            <ixx>9.39482e-06</ixx>
            <ixy>-1.3461e-06</ixy>
            <ixz>0</ixz>
            <iyy>4.07539e-06</iyy>
            <iyz>0</iyz>
            <izz>1.14702e-05</izz>
          </inertia>
        </inertial>
        <collision name='right_gripper_finger3_knuckle_link_collision'>
          <pose frame=''>0 0 0 0 -0 0</pose>
          <geometry>
            <mesh>
              <scale>1 1 1</scale>
              <uri>/home/jeff/movo_ws/src/kinova-movo/movo_common/movo_description/meshes/manipulation/kinova_grippers/collision/finger_knuckle.stl</uri>
            </mesh>
          </geometry>
          <surface>
            <contact>
              <ode>
                <kp>1e+06</kp>
                <kd>1</kd>
                <max_vel>0</max_vel>
                <min_depth>0.0001</min_depth>
              </ode>
            </contact>
            <friction>
              <ode>
                <mu>0.8</mu>
                <mu2>0.8</mu2>
              </ode>
              <torsional>
                <ode/>
              </torsional>
            </friction>
            <bounce/>
          </surface>
          <max_contacts>10</max_contacts>
        </collision>
        <collision name='right_gripper_finger3_knuckle_link_fixed_joint_lump__right_gripper_finger3_finger_tip_link_collision_1'>
          <pose frame=''>-0.024598 -0.036051 0 0 -0 0</pose>
          <geometry>
            <mesh>
              <scale>1 1 1</scale>
              <uri>/home/jeff/movo_ws/src/kinova-movo/movo_common/movo_description/meshes/manipulation/kinova_grippers/collision/finger_tip.stl</uri>
            </mesh>
          </geometry>
          <surface>
            <contact>
              <ode>
                <kp>1e+06</kp>
                <kd>1</kd>
                <max_vel>0</max_vel>
                <min_depth>0.0001</min_depth>
              </ode>
            </contact>
            <friction>
              <ode>
                <mu>0.8</mu>
                <mu2>0.8</mu2>
              </ode>
              <torsional>
                <ode/>
              </torsional>
            </friction>
            <bounce/>
          </surface>
          <max_contacts>10</max_contacts>
        </collision>
        <visual name='right_gripper_finger3_knuckle_link_visual'>
          <pose frame=''>0 0 0 0 -0 0</pose>
          <geometry>
            <mesh>
              <scale>1 1 1</scale>
              <uri>/home/jeff/movo_ws/src/kinova-movo/movo_common/movo_description/meshes/manipulation/kinova_grippers/visual/finger_knuckle.dae</uri>
            </mesh>
          </geometry>
          <material>
            <script>
              <uri>__default__</uri>
              <name>__default__</name>
            </script>
          </material>
        </visual>
        <visual name='right_gripper_finger3_knuckle_link_fixed_joint_lump__right_gripper_finger3_finger_tip_link_visual_1'>
          <pose frame=''>-0.024598 -0.036051 0 0 -0 0</pose>
          <geometry>
            <mesh>
              <scale>1 1 1</scale>
              <uri>/home/jeff/movo_ws/src/kinova-movo/movo_common/movo_description/meshes/manipulation/kinova_grippers/visual/finger_tip.dae</uri>
            </mesh>
          </geometry>
          <material>
            <script>
              <uri>__default__</uri>
              <name>__default__</name>
            </script>
          </material>
        </visual>
        <velocity_decay/>
        <gravity>1</gravity>
        <velocity_decay/>
        <self_collide>0</self_collide>
        <kinematic>0</kinematic>
      </link>
      <joint name='right_gripper_finger3_joint' type='revolute'>
        <child>right_gripper_finger3_knuckle_link</child>
        <parent>right_wrist_3_link</parent>
        <axis>
          <xyz>0 0.982992 0.183648</xyz>
          <limit>
            <lower>0</lower>
            <upper>0.986111</upper>
            <effort>3</effort>
            <velocity>1</velocity>
          </limit>
          <dynamics>
            <spring_reference>0</spring_reference>
            <spring_stiffness>0</spring_stiffness>
          </dynamics>
          <use_parent_model_frame>1</use_parent_model_frame>
        </axis>
      </joint>
      <link name='mid_body_link'>
        <pose frame=''>0.07714 0 0.470076 0 -0 0</pose>
        <inertial>
          <pose frame=''>-0.07714 0 0.026602 0 -0 0</pose>
          <mass>2.24684</mass>
          <inertia>
            <ixx>0.067276</ixx>
            <ixy>0</ixy>
            <ixz>0</ixz>
            <iyy>0.073946</iyy>
            <iyz>0</iyz>
            <izz>0.102656</izz>
          </inertia>
        </inertial>
        <visual name='mid_body_link_visual'>
          <pose frame=''>0 0 0 0 -0 0</pose>
          <geometry>
            <mesh>
              <scale>1 1 1</scale>
              <uri>/home/jeff/movo_ws/src/kinova-movo/movo_common/movo_description/meshes/movo_body/movo_mid_body.dae</uri>
            </mesh>
          </geometry>
          <material>
            <script>
              <uri>__default__</uri>
              <name>__default__</name>
            </script>
          </material>
        </visual>
        <gravity>1</gravity>
        <velocity_decay/>
        <gravity>0</gravity>
        <self_collide>0</self_collide>
        <kinematic>0</kinematic>
      </link>
      <joint name='mid_body_joint' type='prismatic'>
        <child>mid_body_link</child>
        <parent>base_link</parent>
        <axis>
          <xyz>0 0 1</xyz>
          <limit>
            <lower>0</lower>
            <upper>0.254561</upper>
            <effort>1000</effort>
            <velocity>0.2</velocity>
          </limit>
          <dynamics>
            <damping>0</damping>
            <friction>0</friction>
            <spring_reference>0</spring_reference>
            <spring_stiffness>0</spring_stiffness>
          </dynamics>
          <use_parent_model_frame>1</use_parent_model_frame>
        </axis>
      </joint>
      <plugin name='gazebo_ros_control' filename='libgazebo_ros_control.so'>
        <robotNamespace>/</robotNamespace>
      </plugin>
      <plugin name='object_controller' filename='libgazebo_ros_force_based_move.so'>
        <robotNamespace>/</robotNamespace>
        <commandTopic>/movo/cmd_vel</commandTopic>
        <odometryTopic>/movo/odometry/wheel_odometry</odometryTopic>
        <odometryFrame>odom</odometryFrame>
        <odometryRate>100.0</odometryRate>
        <cmdVelTimeOut>0.2</cmdVelTimeOut>
        <robotBaseFrame>base_link</robotBaseFrame>
        <publishOdometryTf>0</publishOdometryTf>
        <yaw_velocity_p_gain>500.0</yaw_velocity_p_gain>
        <x_velocity_p_gain>10000.0</x_velocity_p_gain>
        <y_velocity_p_gain>10000.0</y_velocity_p_gain>
      </plugin>
      <plugin name='gazebo_ros_p3d' filename='libgazebo_ros_p3d.so'>
        <bodyName>base_link</bodyName>
        <topicName>ground_truth_odom</topicName>
        <alwaysOn>true</alwaysOn>
        <updateRate>100.0</updateRate>
        <robotNamespace>/</robotNamespace>
      </plugin>
      <plugin name='sic_imu_controller' filename='libhector_gazebo_ros_imu.so'>
        <alwaysOn>1</alwaysOn>
        <updateRate>50.0</updateRate>
        <topicName>/movo/feedback/sic_imu</topicName>
        <accelDrift>0.0005 0.0005 0.0005</accelDrift>
        <accelGaussianNoise>0.0005 0.0005 0.0005</accelGaussianNoise>
        <rateDrift>0.0005 0.0005 0.0005</rateDrift>
        <rateGaussianNoise>0.00005 0.00005 0.00005</rateGaussianNoise>
        <headingDrift>0.00005</headingDrift>
        <headingGaussianNoise>0.00005</headingGaussianNoise>
        <robotNamespace>/</robotNamespace>
        <bodyName>base_link</bodyName>
        <xyzOffset>-0.0326421 -0.0899448 -0.0844008</xyzOffset>
        <rpyOffset>-0.0548311 -4.63139e-08 0.0274155</rpyOffset>
      </plugin>
      <plugin name='mid_body_mimic' filename='libroboticsgroup_gazebo_mimic_joint_plugin.so'>
        <joint>linear_joint</joint>
        <mimicJoint>mid_body_joint</mimicJoint>
        <multiplier>0.5</multiplier>
        <offset>0.0</offset>
        <maxEffort>100000.0</maxEffort>
        <robotNamespace>/</robotNamespace>
      </plugin>
      <plugin name='right_mimic_finger_1_2' filename='libroboticsgroup_gazebo_mimic_joint_plugin.so'>
        <joint>right_gripper_finger1_joint</joint>
        <mimicJoint>right_gripper_finger2_joint</mimicJoint>
        <robotNamespace>/</robotNamespace>
      </plugin>
      <plugin name='right_mimic_finger_1_3' filename='libroboticsgroup_gazebo_mimic_joint_plugin.so'>
        <joint>right_gripper_finger1_joint</joint>
        <mimicJoint>right_gripper_finger3_joint</mimicJoint>
        <robotNamespace>/</robotNamespace>
      </plugin>
      <plugin name='left_mimic_finger_1_2' filename='libroboticsgroup_gazebo_mimic_joint_plugin.so'>
        <joint>left_gripper_finger1_joint</joint>
        <mimicJoint>left_gripper_finger2_joint</mimicJoint>
        <robotNamespace>/</robotNamespace>
      </plugin>
      <plugin name='left_mimic_finger_1_3' filename='libroboticsgroup_gazebo_mimic_joint_plugin.so'>
        <joint>left_gripper_finger1_joint</joint>
        <mimicJoint>left_gripper_finger3_joint</mimicJoint>
        <robotNamespace>/</robotNamespace>
      </plugin>
      <plugin name='gazebo_right_grasp_fix' filename='libgazebo_grasp_fix.so'>
        <arm>
          <arm_name>right_arm</arm_name>
          <palm_link>right_wrist_3_link</palm_link>
          <gripper_link>right_gripper_finger1_knuckle_link</gripper_link>
          <gripper_link>right_gripper_finger2_knuckle_link</gripper_link>
          <gripper_link>right_gripper_finger3_knuckle_link</gripper_link>
        </arm>
        <forces_angle_tolerance>100</forces_angle_tolerance>
        <update_rate>50</update_rate>
        <grip_count_threshold>1</grip_count_threshold>
        <max_grip_count>8</max_grip_count>
        <release_tolerance>0.006</release_tolerance>
        <disable_collisions_on_attach>true</disable_collisions_on_attach>
        <contact_topic>right_gripper/contacts</contact_topic>
        <robotNamespace>/</robotNamespace>
      </plugin>
      <static>0</static>
      <plugin name='gazebo_left_grasp_fix' filename='libgazebo_grasp_fix.so'>
        <arm>
          <arm_name>left_arm</arm_name>
          <palm_link>left_wrist_3_link</palm_link>
          <gripper_link>left_gripper_finger1_knuckle_link</gripper_link>
          <gripper_link>left_gripper_finger2_knuckle_link</gripper_link>
          <gripper_link>left_gripper_finger3_knuckle_link</gripper_link>
        </arm>
        <forces_angle_tolerance>100</forces_angle_tolerance>
        <update_rate>50</update_rate>
        <grip_count_threshold>1</grip_count_threshold>
        <max_grip_count>8</max_grip_count>
        <release_tolerance>0.006</release_tolerance>
        <disable_collisions_on_attach>true</disable_collisions_on_attach>
        <contact_topic>left_gripper/contacts</contact_topic>
        <robotNamespace>/</robotNamespace>
      </plugin>
      <pose frame=''>0 0 0 0 -0 0</pose>
    </model>
    <light name='user_point_light_0' type='point'>
      <pose frame=''>4.12944 0.277426 1 0 -0 0</pose>
      <diffuse>0.5 0.5 0.5 1</diffuse>
      <specular>0.1 0.1 0.1 1</specular>
      <attenuation>
        <range>20</range>
        <constant>0.5</constant>
        <linear>0.01</linear>
        <quadratic>0.001</quadratic>
      </attenuation>
      <cast_shadows>0</cast_shadows>
      <direction>0 0 -1</direction>
    </light>
    <model name='RGB_room'>
      <pose frame=''>4.5 2.57987 0 0 -0 0</pose>
      <link name='Wall_1'>
        <collision name='Wall_1_Collision'>
          <geometry>
            <box>
              <size>5.98 0.15 2.5</size>
            </box>
          </geometry>
          <pose frame=''>0 0 1.25 0 -0 0</pose>
          <max_contacts>10</max_contacts>
          <surface>
            <contact>
              <ode/>
            </contact>
            <bounce/>
            <friction>
              <torsional>
                <ode/>
              </torsional>
              <ode/>
            </friction>
          </surface>
        </collision>
        <visual name='Wall_1_Visual'>
          <pose frame=''>0 0 1.25 0 -0 0</pose>
          <geometry>
            <box>
              <size>5.98 0.15 2.5</size>
            </box>
          </geometry>
          <material>
            <script>
              <uri>file://media/materials/scripts/gazebo.material</uri>
              <name>Gazebo/Grey</name>
            </script>
            <ambient>1 1 1 1</ambient>
          </material>
          <meta>
            <layer>0</layer>
          </meta>
        </visual>
        <pose frame=''>-2.585 -5.84987 0 0 -0 0</pose>
        <self_collide>0</self_collide>
        <kinematic>0</kinematic>
      </link>
      <link name='Wall_11'>
        <collision name='Wall_11_Collision'>
          <geometry>
            <box>
              <size>6 0.15 2.5</size>
            </box>
          </geometry>
          <pose frame=''>0 0 1.25 0 -0 0</pose>
          <max_contacts>10</max_contacts>
          <surface>
            <contact>
              <ode/>
            </contact>
            <bounce/>
            <friction>
              <torsional>
                <ode/>
              </torsional>
              <ode/>
            </friction>
          </surface>
        </collision>
        <visual name='Wall_11_Visual'>
          <pose frame=''>0 0 1.25 0 -0 0</pose>
          <geometry>
            <box>
              <size>6 0.15 2.5</size>
            </box>
          </geometry>
          <material>
            <script>
              <uri>file://media/materials/scripts/gazebo.material</uri>
              <name>Gazebo/Grey</name>
            </script>
            <ambient>1 1 1 1</ambient>
          </material>
          <meta>
            <layer>0</layer>
          </meta>
        </visual>
        <pose frame=''>-5.5 2.92513 0 0 -0 1.5708</pose>
        <self_collide>0</self_collide>
        <kinematic>0</kinematic>
      </link>
      <link name='Wall_12'>
        <collision name='Wall_12_Collision'>
          <geometry>
            <box>
              <size>6 0.15 2.5</size>
            </box>
          </geometry>
          <pose frame=''>0 0 1.25 0 -0 0</pose>
          <max_contacts>10</max_contacts>
          <surface>
            <contact>
              <ode/>
            </contact>
            <bounce/>
            <friction>
              <torsional>
                <ode/>
              </torsional>
              <ode/>
            </friction>
          </surface>
        </collision>
        <visual name='Wall_12_Visual'>
          <pose frame=''>0 0 1.25 0 -0 0</pose>
          <geometry>
            <box>
              <size>6 0.15 2.5</size>
            </box>
          </geometry>
          <material>
            <script>
              <uri>file://media/materials/scripts/gazebo.material</uri>
              <name>Gazebo/Grey</name>
            </script>
            <ambient>1 1 1 1</ambient>
          </material>
          <meta>
            <layer>0</layer>
          </meta>
        </visual>
        <pose frame=''>-2.575 5.85013 0 0 -0 0</pose>
        <self_collide>0</self_collide>
        <kinematic>0</kinematic>
      </link>
      <link name='Wall_14'>
        <pose frame=''>0.34 -2.92487 0 0 0 -1.57421</pose>
        <visual name='Wall_14_Visual_0'>
          <pose frame=''>-1.72481 0 1.25 0 -0 0</pose>
          <geometry>
            <box>
              <size>2.5504 0.15 2.5</size>
            </box>
          </geometry>
          <material>
            <script>
              <uri>file://media/materials/scripts/gazebo.material</uri>
              <name>Gazebo/Grey</name>
            </script>
            <ambient>1 1 1 1</ambient>
          </material>
          <meta>
            <layer>0</layer>
          </meta>
        </visual>
        <collision name='Wall_14_Collision_0'>
          <geometry>
            <box>
              <size>2.5504 0.15 2.5</size>
            </box>
          </geometry>
          <pose frame=''>-1.72481 0 1.25 0 -0 0</pose>
          <max_contacts>10</max_contacts>
          <surface>
            <contact>
              <ode/>
            </contact>
            <bounce/>
            <friction>
              <torsional>
                <ode/>
              </torsional>
              <ode/>
            </friction>
          </surface>
        </collision>
        <visual name='Wall_14_Visual_1'>
          <pose frame=''>1.7252 0 1.25 0 -0 0</pose>
          <geometry>
            <box>
              <size>2.54963 0.15 2.5</size>
            </box>
          </geometry>
          <material>
            <script>
              <uri>file://media/materials/scripts/gazebo.material</uri>
              <name>Gazebo/Grey</name>
            </script>
            <ambient>1 1 1 1</ambient>
          </material>
          <meta>
            <layer>0</layer>
          </meta>
        </visual>
        <collision name='Wall_14_Collision_1'>
          <geometry>
            <box>
              <size>2.54963 0.15 2.5</size>
            </box>
          </geometry>
          <pose frame=''>1.7252 0 1.25 0 -0 0</pose>
          <max_contacts>10</max_contacts>
          <surface>
            <contact>
              <ode/>
            </contact>
            <bounce/>
            <friction>
              <torsional>
                <ode/>
              </torsional>
              <ode/>
            </friction>
          </surface>
        </collision>
        <visual name='Wall_14_Visual_2'>
          <pose frame=''>0.000387 0 2.25 0 -0 0</pose>
          <geometry>
            <box>
              <size>0.9 0.15 0.5</size>
            </box>
          </geometry>
          <material>
            <script>
              <uri>file://media/materials/scripts/gazebo.material</uri>
              <name>Gazebo/Grey</name>
            </script>
            <ambient>1 1 1 1</ambient>
          </material>
          <meta>
            <layer>0</layer>
          </meta>
        </visual>
        <collision name='Wall_14_Collision_2'>
          <geometry>
            <box>
              <size>0.9 0.15 0.5</size>
            </box>
          </geometry>
          <pose frame=''>0.000387 0 2.25 0 -0 0</pose>
          <max_contacts>10</max_contacts>
          <surface>
            <contact>
              <ode/>
            </contact>
            <bounce/>
            <friction>
              <torsional>
                <ode/>
              </torsional>
              <ode/>
            </friction>
          </surface>
        </collision>
        <self_collide>0</self_collide>
        <kinematic>0</kinematic>
      </link>
      <link name='Wall_16'>
        <collision name='Wall_16_Collision'>
          <geometry>
            <box>
              <size>5.32 0.15 2.5</size>
            </box>
          </geometry>
          <pose frame=''>0 0 1.25 0 -0 0</pose>
          <max_contacts>10</max_contacts>
          <surface>
            <contact>
              <ode/>
            </contact>
            <bounce/>
            <friction>
              <torsional>
                <ode/>
              </torsional>
              <ode/>
            </friction>
          </surface>
        </collision>
        <visual name='Wall_16_Visual'>
          <pose frame=''>0 0 1.25 0 -0 0</pose>
          <geometry>
            <box>
              <size>5.32 0.15 2.5</size>
            </box>
          </geometry>
          <material>
            <script>
              <uri>file://media/materials/scripts/gazebo.material</uri>
              <name>Gazebo/Grey</name>
            </script>
            <ambient>1 1 1 1</ambient>
          </material>
          <meta>
            <layer>0</layer>
          </meta>
        </visual>
        <pose frame=''>2.915 -5.84987 0 0 -0 0</pose>
        <self_collide>0</self_collide>
        <kinematic>0</kinematic>
      </link>
      <link name='Wall_19'>
        <pose frame=''>0.35 2.92513 0 0 0 -1.5708</pose>
        <visual name='Wall_19_Visual_0'>
          <pose frame=''>-1.72814 0 1.25 0 -0 0</pose>
          <geometry>
            <box>
              <size>2.54371 0.15 2.5</size>
            </box>
          </geometry>
          <material>
            <script>
              <uri>file://media/materials/scripts/gazebo.material</uri>
              <name>Gazebo/Grey</name>
            </script>
            <ambient>1 1 1 1</ambient>
          </material>
          <meta>
            <layer>0</layer>
          </meta>
        </visual>
        <collision name='Wall_19_Collision_0'>
          <geometry>
            <box>
              <size>2.54371 0.15 2.5</size>
            </box>
          </geometry>
          <pose frame=''>-1.72814 0 1.25 0 -0 0</pose>
          <max_contacts>10</max_contacts>
          <surface>
            <contact>
              <ode/>
            </contact>
            <bounce/>
            <friction>
              <torsional>
                <ode/>
              </torsional>
              <ode/>
            </friction>
          </surface>
        </collision>
        <visual name='Wall_19_Visual_1'>
          <pose frame=''>1.72186 0 1.25 0 -0 0</pose>
          <geometry>
            <box>
              <size>2.55629 0.15 2.5</size>
            </box>
          </geometry>
          <material>
            <script>
              <uri>file://media/materials/scripts/gazebo.material</uri>
              <name>Gazebo/Grey</name>
            </script>
            <ambient>1 1 1 1</ambient>
          </material>
          <meta>
            <layer>0</layer>
          </meta>
        </visual>
        <collision name='Wall_19_Collision_1'>
          <geometry>
            <box>
              <size>2.55629 0.15 2.5</size>
            </box>
          </geometry>
          <pose frame=''>1.72186 0 1.25 0 -0 0</pose>
          <max_contacts>10</max_contacts>
          <surface>
            <contact>
              <ode/>
            </contact>
            <bounce/>
            <friction>
              <torsional>
                <ode/>
              </torsional>
              <ode/>
            </friction>
          </surface>
        </collision>
        <visual name='Wall_19_Visual_2'>
          <pose frame=''>-0.006289 0 2.25 0 -0 0</pose>
          <geometry>
            <box>
              <size>0.9 0.15 0.5</size>
            </box>
          </geometry>
          <material>
            <script>
              <uri>file://media/materials/scripts/gazebo.material</uri>
              <name>Gazebo/Grey</name>
            </script>
            <ambient>1 1 1 1</ambient>
          </material>
          <meta>
            <layer>0</layer>
          </meta>
        </visual>
        <collision name='Wall_19_Collision_2'>
          <geometry>
            <box>
              <size>0.9 0.15 0.5</size>
            </box>
          </geometry>
          <pose frame=''>-0.006289 0 2.25 0 -0 0</pose>
          <max_contacts>10</max_contacts>
          <surface>
            <contact>
              <ode/>
            </contact>
            <bounce/>
            <friction>
              <torsional>
                <ode/>
              </torsional>
              <ode/>
            </friction>
          </surface>
        </collision>
        <self_collide>0</self_collide>
        <kinematic>0</kinematic>
      </link>
      <link name='Wall_24'>
        <collision name='Wall_24_Collision'>
          <geometry>
            <box>
              <size>5.3 0.15 2.5</size>
            </box>
          </geometry>
          <pose frame=''>0 0 1.25 0 -0 0</pose>
          <max_contacts>10</max_contacts>
          <surface>
            <contact>
              <ode/>
            </contact>
            <bounce/>
            <friction>
              <torsional>
                <ode/>
              </torsional>
              <ode/>
            </friction>
          </surface>
        </collision>
        <visual name='Wall_24_Visual'>
          <pose frame=''>0 0 1.25 0 -0 0</pose>
          <geometry>
            <box>
              <size>5.3 0.15 2.5</size>
            </box>
          </geometry>
          <material>
            <script>
              <uri>file://media/materials/scripts/gazebo.material</uri>
              <name>Gazebo/Grey</name>
            </script>
            <ambient>1 1 1 1</ambient>
          </material>
          <meta>
            <layer>0</layer>
          </meta>
        </visual>
        <pose frame=''>2.925 5.85013 0 0 -0 0</pose>
        <self_collide>0</self_collide>
        <kinematic>0</kinematic>
      </link>
      <link name='Wall_27'>
        <collision name='Wall_27_Collision'>
          <geometry>
            <box>
              <size>11.85 0.15 2.5</size>
            </box>
          </geometry>
          <pose frame=''>0 0 1.25 0 -0 0</pose>
          <max_contacts>10</max_contacts>
          <surface>
            <contact>
              <ode/>
            </contact>
            <bounce/>
            <friction>
              <torsional>
                <ode/>
              </torsional>
              <ode/>
            </friction>
          </surface>
        </collision>
        <visual name='Wall_27_Visual'>
          <pose frame=''>0 0 1.25 0 -0 0</pose>
          <geometry>
            <box>
              <size>11.85 0.15 2.5</size>
            </box>
          </geometry>
          <material>
            <script>
              <uri>file://media/materials/scripts/gazebo.material</uri>
              <name>Gazebo/Grey</name>
            </script>
            <ambient>1 1 1 1</ambient>
          </material>
          <meta>
            <layer>0</layer>
          </meta>
        </visual>
        <pose frame=''>5.5 0.000127 0 0 0 -1.5708</pose>
        <self_collide>0</self_collide>
        <kinematic>0</kinematic>
      </link>
      <link name='Wall_3'>
        <collision name='Wall_3_Collision'>
          <geometry>
            <box>
              <size>6 0.15 2.5</size>
            </box>
          </geometry>
          <pose frame=''>0 0 1.25 0 -0 0</pose>
          <max_contacts>10</max_contacts>
          <surface>
            <contact>
              <ode/>
            </contact>
            <bounce/>
            <friction>
              <torsional>
                <ode/>
              </torsional>
              <ode/>
            </friction>
          </surface>
        </collision>
        <visual name='Wall_3_Visual'>
          <pose frame=''>0 0 1.25 0 -0 0</pose>
          <geometry>
            <box>
              <size>6 0.15 2.5</size>
            </box>
          </geometry>
          <material>
            <script>
              <uri>file://media/materials/scripts/gazebo.material</uri>
              <name>Gazebo/Grey</name>
            </script>
            <ambient>1 1 1 1</ambient>
          </material>
          <meta>
            <layer>0</layer>
          </meta>
        </visual>
        <pose frame=''>-5.5 -2.92487 0 0 -0 1.5708</pose>
        <self_collide>0</self_collide>
        <kinematic>0</kinematic>
      </link>
      <link name='Wall_4'>
        <collision name='Wall_4_Collision'>
          <geometry>
            <box>
              <size>6 0.15 2.5</size>
            </box>
          </geometry>
          <pose frame=''>0 0 1.25 0 -0 0</pose>
          <max_contacts>10</max_contacts>
          <surface>
            <contact>
              <ode/>
            </contact>
            <bounce/>
            <friction>
              <torsional>
                <ode/>
              </torsional>
              <ode/>
            </friction>
          </surface>
        </collision>
        <visual name='Wall_4_Visual'>
          <pose frame=''>0 0 1.25 0 -0 0</pose>
          <geometry>
            <box>
              <size>6 0.15 2.5</size>
            </box>
          </geometry>
          <material>
            <script>
              <uri>file://media/materials/scripts/gazebo.material</uri>
              <name>Gazebo/Grey</name>
            </script>
            <ambient>1 1 1 1</ambient>
          </material>
          <meta>
            <layer>0</layer>
          </meta>
        </visual>
        <pose frame=''>-2.575 0.000127 0 0 -0 0</pose>
        <self_collide>0</self_collide>
        <kinematic>0</kinematic>
      </link>
      <static>1</static>
    </model>
    <model name='table'>
      <static>1</static>
      <link name='link'>
        <collision name='surface'>
          <pose frame=''>0 0 1 0 -0 0</pose>
          <geometry>
            <box>
              <size>1.5 0.8 0.03</size>
            </box>
          </geometry>
          <surface>
            <friction>
              <ode>
                <mu>0.6</mu>
                <mu2>0.6</mu2>
              </ode>
              <torsional>
                <ode/>
              </torsional>
            </friction>
            <contact>
              <ode/>
            </contact>
            <bounce/>
          </surface>
          <max_contacts>10</max_contacts>
        </collision>
        <visual name='visual1'>
          <pose frame=''>0 0 1 0 -0 0</pose>
          <geometry>
            <box>
              <size>1.5 0.8 0.03</size>
            </box>
          </geometry>
          <material>
            <script>
              <uri>file://media/materials/scripts/gazebo.material</uri>
              <name>Gazebo/Wood</name>
            </script>
          </material>
        </visual>
        <collision name='front_left_leg'>
          <pose frame=''>0.68 0.38 0.5 0 -0 0</pose>
          <geometry>
            <cylinder>
              <radius>0.02</radius>
              <length>1</length>
            </cylinder>
          </geometry>
          <max_contacts>10</max_contacts>
          <surface>
            <contact>
              <ode/>
            </contact>
            <bounce/>
            <friction>
              <torsional>
                <ode/>
              </torsional>
              <ode/>
            </friction>
          </surface>
        </collision>
        <visual name='front_left_leg'>
          <pose frame=''>0.68 0.38 0.5 0 -0 0</pose>
          <geometry>
            <cylinder>
              <radius>0.02</radius>
              <length>1</length>
            </cylinder>
          </geometry>
          <material>
            <script>
              <uri>file://media/materials/scripts/gazebo.material</uri>
              <name>Gazebo/Grey</name>
            </script>
          </material>
        </visual>
        <collision name='front_right_leg'>
          <pose frame=''>0.68 -0.38 0.5 0 -0 0</pose>
          <geometry>
            <cylinder>
              <radius>0.02</radius>
              <length>1</length>
            </cylinder>
          </geometry>
          <max_contacts>10</max_contacts>
          <surface>
            <contact>
              <ode/>
            </contact>
            <bounce/>
            <friction>
              <torsional>
                <ode/>
              </torsional>
              <ode/>
            </friction>
          </surface>
        </collision>
        <visual name='front_right_leg'>
          <pose frame=''>0.68 -0.38 0.5 0 -0 0</pose>
          <geometry>
            <cylinder>
              <radius>0.02</radius>
              <length>1</length>
            </cylinder>
          </geometry>
          <material>
            <script>
              <uri>file://media/materials/scripts/gazebo.material</uri>
              <name>Gazebo/Grey</name>
            </script>
          </material>
        </visual>
        <collision name='back_right_leg'>
          <pose frame=''>-0.68 -0.38 0.5 0 -0 0</pose>
          <geometry>
            <cylinder>
              <radius>0.02</radius>
              <length>1</length>
            </cylinder>
          </geometry>
          <max_contacts>10</max_contacts>
          <surface>
            <contact>
              <ode/>
            </contact>
            <bounce/>
            <friction>
              <torsional>
                <ode/>
              </torsional>
              <ode/>
            </friction>
          </surface>
        </collision>
        <visual name='back_right_leg'>
          <pose frame=''>-0.68 -0.38 0.5 0 -0 0</pose>
          <geometry>
            <cylinder>
              <radius>0.02</radius>
              <length>1</length>
            </cylinder>
          </geometry>
          <material>
            <script>
              <uri>file://media/materials/scripts/gazebo.material</uri>
              <name>Gazebo/Grey</name>
            </script>
          </material>
        </visual>
        <collision name='back_left_leg'>
          <pose frame=''>-0.68 0.38 0.5 0 -0 0</pose>
          <geometry>
            <cylinder>
              <radius>0.02</radius>
              <length>1</length>
            </cylinder>
          </geometry>
          <max_contacts>10</max_contacts>
          <surface>
            <contact>
              <ode/>
            </contact>
            <bounce/>
            <friction>
              <torsional>
                <ode/>
              </torsional>
              <ode/>
            </friction>
          </surface>
        </collision>
        <visual name='back_left_leg'>
          <pose frame=''>-0.68 0.38 0.5 0 -0 0</pose>
          <geometry>
            <cylinder>
              <radius>0.02</radius>
              <length>1</length>
            </cylinder>
          </geometry>
          <material>
            <script>
              <uri>file://media/materials/scripts/gazebo.material</uri>
              <name>Gazebo/Grey</name>
            </script>
          </material>
        </visual>
        <self_collide>0</self_collide>
        <kinematic>0</kinematic>
      </link>
      <pose frame=''>2.18465 5.14262 0 0 -0 0</pose>
    </model>
    <model name='beer'>
      <link name='link'>
        <pose frame=''>0 0 0.115 0 -0 0</pose>
        <inertial>
          <mass>0.39</mass>
          <inertia>
            <ixx>0.00058</ixx>
            <ixy>0</ixy>
            <ixz>0</ixz>
            <iyy>0.00058</iyy>
            <iyz>0</iyz>
            <izz>0.00019</izz>
          </inertia>
        </inertial>
        <collision name='collision'>
          <geometry>
            <cylinder>
              <radius>0.055</radius>
              <length>0.23</length>
            </cylinder>
          </geometry>
          <max_contacts>10</max_contacts>
          <surface>
            <contact>
              <ode/>
            </contact>
            <bounce/>
            <friction>
              <torsional>
                <ode/>
              </torsional>
              <ode/>
            </friction>
          </surface>
        </collision>
        <visual name='visual'>
          <geometry>
            <cylinder>
              <radius>0.055</radius>
              <length>0.23</length>
            </cylinder>
          </geometry>
          <material>
            <script>
              <uri>model://beer/materials/scripts</uri>
              <uri>model://beer/materials/textures</uri>
              <name>Beer/Diffuse</name>
            </script>
          </material>
        </visual>
        <self_collide>0</self_collide>
        <kinematic>0</kinematic>
      </link>
      <pose frame=''>0.187037 4.55848 0 0 -0 0</pose>
    </model>
    <state world_name='default'>
      <sim_time>806 141000000</sim_time>
      <real_time>929 828137679</real_time>
      <wall_time>1524021954 518790418</wall_time>
      <iterations>806141</iterations>
      <model name='RGB_room'>
        <pose frame=''>4.24777 2.36231 0 0 -0 0</pose>
        <scale>1 1 1</scale>
        <link name='Wall_1'>
          <pose frame=''>1.66277 -3.48756 0 0 -0 0</pose>
          <velocity>0 0 0 0 -0 0</velocity>
          <acceleration>0 0 0 0 -0 0</acceleration>
          <wrench>0 0 0 0 -0 0</wrench>
        </link>
        <link name='Wall_11'>
          <pose frame=''>-1.25223 5.28744 0 0 -0 1.5708</pose>
          <velocity>0 0 0 0 -0 0</velocity>
          <acceleration>0 0 0 0 -0 0</acceleration>
          <wrench>0 0 0 0 -0 0</wrench>
        </link>
        <link name='Wall_12'>
          <pose frame=''>1.67277 8.21244 0 0 -0 0</pose>
          <velocity>0 0 0 0 -0 0</velocity>
          <acceleration>0 0 0 0 -0 0</acceleration>
          <wrench>0 0 0 0 -0 0</wrench>
        </link>
        <link name='Wall_14'>
          <pose frame=''>4.58777 -0.562556 0 0 0 -1.57421</pose>
          <velocity>0 0 0 0 -0 0</velocity>
          <acceleration>0 0 0 0 -0 0</acceleration>
          <wrench>0 0 0 0 -0 0</wrench>
        </link>
        <link name='Wall_16'>
          <pose frame=''>7.16277 -3.48756 0 0 -0 0</pose>
          <velocity>0 0 0 0 -0 0</velocity>
          <acceleration>0 0 0 0 -0 0</acceleration>
          <wrench>0 0 0 0 -0 0</wrench>
        </link>
        <link name='Wall_19'>
          <pose frame=''>4.59777 5.28744 0 0 0 -1.5708</pose>
          <velocity>0 0 0 0 -0 0</velocity>
          <acceleration>0 0 0 0 -0 0</acceleration>
          <wrench>0 0 0 0 -0 0</wrench>
        </link>
        <link name='Wall_24'>
          <pose frame=''>7.17277 8.21244 0 0 -0 0</pose>
          <velocity>0 0 0 0 -0 0</velocity>
          <acceleration>0 0 0 0 -0 0</acceleration>
          <wrench>0 0 0 0 -0 0</wrench>
        </link>
        <link name='Wall_27'>
          <pose frame=''>9.74777 2.36244 0 0 0 -1.5708</pose>
          <velocity>0 0 0 0 -0 0</velocity>
          <acceleration>0 0 0 0 -0 0</acceleration>
          <wrench>0 0 0 0 -0 0</wrench>
        </link>
        <link name='Wall_3'>
          <pose frame=''>-1.25223 -0.562556 0 0 -0 1.5708</pose>
          <velocity>0 0 0 0 -0 0</velocity>
          <acceleration>0 0 0 0 -0 0</acceleration>
          <wrench>0 0 0 0 -0 0</wrench>
        </link>
        <link name='Wall_4'>
          <pose frame=''>1.67277 2.36244 0 0 -0 0</pose>
          <velocity>0 0 0 0 -0 0</velocity>
          <acceleration>0 0 0 0 -0 0</acceleration>
          <wrench>0 0 0 0 -0 0</wrench>
        </link>
      </model>
      <model name='beer'>
        <pose frame=''>-0.06839 4.55849 0.356315 -1.5e-05 -5e-06 0.000849</pose>
        <scale>1 1 1</scale>
        <link name='link'>
          <pose frame=''>-0.068391 4.55849 0.471315 -1.5e-05 -5e-06 0.000849</pose>
          <velocity>0 0 0 0 -0 0</velocity>
          <acceleration>1.18003 -3.22139 3.31667 -0.198185 -0.487416 2.41748</acceleration>
          <wrench>0.46021 -1.25634 1.2935 0 -0 0</wrench>
        </link>
      </model>
      <model name='ground_plane'>
        <pose frame=''>0 0 0 0 -0 0</pose>
        <scale>1 1 1</scale>
        <link name='link'>
          <pose frame=''>0 0 0 0 -0 0</pose>
          <velocity>0 0 0 0 -0 0</velocity>
          <acceleration>0 0 0 0 -0 0</acceleration>
          <wrench>0 0 0 0 -0 0</wrench>
        </link>
      </model>
      <model name='movo'>
        <pose frame=''>-0.076608 0.275573 0 0 -0 0.538133</pose>
        <scale>1 1 1</scale>
        <link name='base_link'>
          <pose frame=''>-0.076608 0.275573 0 0 -0 0.538133</pose>
          <velocity>-2e-06 0.002224 0.001744 0.003785 -0.006273 2.4e-05</velocity>
          <acceleration>-2.98938 1.11354 3.43543 -0.983405 0.171251 2.28652</acceleration>
          <wrench>-203.034 75.6301 233.329 0 -0 0</wrench>
        </link>
        <link name='left_arm_half_1_link'>
          <pose frame=''>0.099324 0.535902 0.750016 0.00165 0.006985 2.1037</pose>
          <velocity>-0.00474 -0.000656 0.003968 -0.017293 -0.004991 -0.013209</velocity>
          <acceleration>-4.04382 -1.83681 3.50313 2.87687 -0.266708 -2.73833</acceleration>
          <wrench>-3.41582 -1.55155 2.9591 0 -0 0</wrench>
        </link>
        <link name='left_arm_half_2_link'>
          <pose frame=''>0.275899 0.640049 0.749829 -1.56858 0.006651 2.1037</pose>
          <velocity>-0.003384 -0.002974 0.004241 -0.018355 0.000282 -0.013314</velocity>
          <acceleration>-2.69254 -4.15059 3.26308 2.0158 0.432439 1.91838</acceleration>
          <wrench>-2.27439 -3.50601 2.75633 0 -0 0</wrench>
        </link>
        <link name='left_forearm_link'>
          <pose frame=''>0.452474 0.744194 0.749486 -3.13952 0.006597 2.10494</pose>
          <velocity>-0.002014 -0.00533 0.003073 -0.017851 -0.000806 -0.00926</velocity>
          <acceleration>-1.63888 -5.82543 2.39182 2.41717 -0.224321 2.61305</acceleration>
          <wrench>-1.10502 -3.92782 1.61269 0 -0 0</wrench>
        </link>
        <link name='left_gripper_finger1_knuckle_link'>
          <pose frame=''>0.909041 1.01217 0.728387 3.0753 -1.39181 -1.0703</pose>
          <velocity>-0.001462 -0.006644 -0.000722 0.020714 -0.031024 -0.002733</velocity>
          <acceleration>-0.537946 -6.1343 0.489646 1.98676 -1.03719 1.28885</acceleration>
          <wrench>-0.011736 -0.133832 0.010683 0 -0 0</wrench>
        </link>
        <link name='left_gripper_finger2_knuckle_link'>
          <pose frame=''>0.896345 1.03383 0.786946 3.12851 1.38562 -1.04523</pose>
          <velocity>-0.001149 -0.006799 -0.000488 0.003127 0.00706 0.004723</velocity>
          <acceleration>-1.05354 -6.76614 -0.600125 1.29453 -0.125506 0.828801</acceleration>
          <wrench>-0.022985 -0.147617 -0.013093 0 -0 0</wrench>
        </link>
        <link name='left_gripper_finger3_knuckle_link'>
          <pose frame=''>0.919219 0.995578 0.786937 0.013116 1.38654 2.12212</pose>
          <velocity>-0.000963 -0.006701 -0.000742 0.002815 0.007644 0.004569</velocity>
          <acceleration>-0.807135 -6.63907 -0.940691 -2.45575 -0.455758 2.07525</acceleration>
          <wrench>-0.017609 -0.144845 -0.020523 0 -0 0</wrench>
        </link>
        <link name='left_shoulder_link'>
          <pose frame=''>-0.002638 0.475028 0.750066 -1.57045 0.006956 2.10914</pose>
          <velocity>-0.004763 -0.000606 0.002964 -0.011337 -0.013632 -0.001405</velocity>
          <acceleration>-4.78232 -0.626479 3.32025 -0.968375 0.962416 -0.800442</acceleration>
          <wrench>-3.94314 -0.516547 2.73763 0 -0 0</wrench>
        </link>
        <link name='left_wrist_3_link'>
          <pose frame=''>0.809245 0.955832 0.759979 -1.5684 0.000453 2.10923</pose>
          <velocity>-0.000946 -0.007158 -9.6e-05 0.002776 0.007428 0.004705</velocity>
          <acceleration>-1.14804 -6.78084 -0.572744 -0.540008 1.11715 1.9092</acceleration>
          <wrench>-1.13667 -6.71367 -0.56707 0 -0 0</wrench>
        </link>
        <link name='left_wrist_spherical_1_link'>
          <pose frame=''>0.630881 0.849807 0.760455 1.56847 -0.000485 -1.0365</pose>
          <velocity>-0.001094 -0.006789 0.001274 0.001813 0.008456 -0.010456</velocity>
          <acceleration>-0.782232 -7.28131 0.929557 3.06676 -0.749299 -2.97081</acceleration>
          <wrench>-0.362173 -3.37125 0.430385 0 -0 0</wrench>
        </link>
        <link name='left_wrist_spherical_2_link'>
          <pose frame=''>0.720172 0.902634 0.760225 -0.002435 -0.000475 -1.03234</pose>
          <velocity>-0.000647 -0.007641 0.000479 0.00281 0.006675 0.004603</velocity>
          <acceleration>-0.783872 -7.4364 0.2661 2.17742 0.433989 -1.0713</acceleration>
          <wrench>-0.362933 -3.44306 0.123204 0 -0 0</wrench>
        </link>
        <link name='linear_actuator_link'>
          <pose frame=''>-0.010372 0.315109 0.470076 -1e-06 3e-06 0.538143</pose>
          <velocity>-0.002951 0.000462 0.002284 0.003762 -0.006301 0.00023</velocity>
          <acceleration>-5.18889 -0.891241 1.80623 -2.4521 -0.040207 0.3275</acceleration>
          <wrench>-107.637 -18.4876 37.4679 0 -0 0</wrench>
        </link>
        <link name='mid_body_link'>
          <pose frame=''>-0.010371 0.31511 0.470076 0 -0 0.538138</pose>
          <velocity>-0.002958 0.00046 0.002308 0.003778 -0.00626 0.000228</velocity>
          <acceleration>-3.1159 0.344257 1.74427 -0.55488 0.577511 -2.89781</acceleration>
          <wrench>-7.00094 0.773491 3.9191 0 -0 0</wrench>
        </link>
        <link name='pan_link'>
          <pose frame=''>0.15908 0.416258 0.870316 3.14158 -1.3e-05 0.538142</pose>
          <velocity>-0.006488 -0.001465 0.003818 0.003968 -0.006627 0.001761</velocity>
          <acceleration>-6.8019 -1.65368 3.81799 -1.54158 -1.19044 -0.30221</acceleration>
          <wrench>-3.20062 -0.778137 1.79655 0 -0 0</wrench>
        </link>
        <link name='right_arm_half_1_link'>
          <pose frame=''>0.23602 0.306896 0.750019 0.001656 0.004153 2.10383</pose>
          <velocity>-0.0047 -0.000636 0.004213 -0.017275 -0.005272 -0.013118</velocity>
          <acceleration>-4.00851 -1.80895 3.77383 1.75204 -1.01303 2.98448</acceleration>
          <wrench>-3.38599 -1.52802 3.18775 0 -0 0</wrench>
        </link>
        <link name='right_arm_half_2_link'>
          <pose frame=''>0.41258 0.411066 0.749831 -1.56858 0.004108 2.10383</pose>
          <velocity>-0.003357 -0.002945 0.004615 -0.018918 0.001016 -0.013255</velocity>
          <acceleration>-2.6687 -4.1164 3.54235 -0.116105 0.948054 -1.26279</acceleration>
          <wrench>-2.25425 -3.47712 2.99222 0 -0 0</wrench>
        </link>
        <link name='right_forearm_link'>
          <pose frame=''>0.589142 0.515234 0.749487 -3.13951 0.004052 2.10511</pose>
          <velocity>-0.002002 -0.005293 0.003362 -0.018392 -0.000235 -0.009214</velocity>
          <acceleration>-1.624 -5.78015 2.61931 -1.4913 -0.49034 -0.580248</acceleration>
          <wrench>-1.09499 -3.89729 1.76608 0 -0 0</wrench>
        </link>
        <link name='right_gripper_finger1_knuckle_link'>
          <pose frame=''>1.0456 0.783396 0.728379 3.07558 -1.38883 -1.07016</pose>
          <velocity>-0.001459 -0.006648 -0.000757 0.003625 0.005052 0.004027</velocity>
          <acceleration>-1.67483 -6.4378 -0.827019 2.47275 0.260005 0.818947</acceleration>
          <wrench>-0.03654 -0.140453 -0.018043 0 -0 0</wrench>
        </link>
        <link name='right_gripper_finger2_knuckle_link'>
          <pose frame=''>1.03298 0.804906 0.787013 3.12835 1.38861 -1.04495</pose>
          <velocity>-0.001162 -0.006742 -0.000562 0.002615 0.007265 0.004306</velocity>
          <acceleration>-1.05143 -6.70592 -0.690613 0.227105 -0.419159 0.1889</acceleration>
          <wrench>-0.022939 -0.146303 -0.015067 0 -0 0</wrench>
        </link>
        <link name='right_gripper_finger3_knuckle_link'>
          <pose frame=''>1.05587 0.76666 0.78687 0.012868 1.38355 2.12232</pose>
          <velocity>-0.000994 -0.006659 -0.000795 0.002205 0.008015 0.004167</velocity>
          <acceleration>-0.822584 -6.59268 -1.01322 1.34085 -0.6653 2.71637</acceleration>
          <wrench>-0.017946 -0.143832 -0.022105 0 -0 0</wrench>
        </link>
        <link name='right_shoulder_link'>
          <pose frame=''>0.134057 0.246022 0.750067 -1.57046 0.004125 2.10914</pose>
          <velocity>-0.004713 -0.00058 0.002981 -0.011377 -0.014246 -0.00143</velocity>
          <acceleration>-4.73448 -0.601684 3.36847 -2.2396 -0.433227 -0.710611</acceleration>
          <wrench>-3.90369 -0.496103 2.77739 0 -0 0</wrench>
        </link>
        <link name='right_wrist_3_link'>
          <pose frame=''>0.945877 0.726934 0.759979 -1.5684 -0.002538 2.10967</pose>
          <velocity>-0.00099 -0.007078 -0.00012 0.002225 0.007653 0.004268</velocity>
          <acceleration>-1.16966 -6.73494 -0.641425 -2.38105 0.581341 2.4488</acceleration>
          <wrench>-1.15808 -6.66822 -0.635071 0 -0 0</wrench>
        </link>
        <link name='right_wrist_spherical_1_link'>
          <pose frame=''>0.767546 0.620854 0.760455 1.56846 0.002487 -1.03633</pose>
          <velocity>-0.001107 -0.006724 0.001399 0.000998 0.008817 -0.010542</velocity>
          <acceleration>-0.791913 -7.21811 1.01483 1.82805 -0.705037 3.05549</acceleration>
          <wrench>-0.366656 -3.34198 0.469867 0 -0 0</wrench>
        </link>
        <link name='right_wrist_spherical_2_link'>
          <pose frame=''>0.856828 0.673696 0.760224 -0.002428 0.002499 -1.0319</pose>
          <velocity>-0.000692 -0.00755 0.000514 0.002282 0.006822 0.004035</velocity>
          <acceleration>-0.815119 -7.37121 0.281199 1.68749 0.437889 -1.4059</acceleration>
          <wrench>-0.3774 -3.41287 0.130195 0 -0 0</wrench>
        </link>
        <link name='tilt_link'>
          <pose frame=''>0.172404 0.393931 0.961066 -0.395361 -1.57079 2.5043</pose>
          <velocity>-0.006921 -0.001813 0.003804 0.003312 -0.005187 0.003084</velocity>
          <acceleration>-7.1086 -1.90402 3.85218 2.99355 1.15931 1.38188</acceleration>
          <wrench>-13.0408 -3.49295 7.06686 0 -0 0</wrench>
        </link>
      </model>
      <model name='table'>
        <pose frame=''>-0.064793 4.99219 -0.658686 0 -0 1.58</pose>
        <scale>1 1 1</scale>
        <link name='link'>
          <pose frame=''>-0.064793 4.99219 -0.658686 0 -0 1.58</pose>
          <velocity>0 0 0 0 -0 0</velocity>
          <acceleration>0 0 0 0 -0 0</acceleration>
          <wrench>0 0 0 0 -0 0</wrench>
        </link>
      </model>
      <light name='sun'>
        <pose frame=''>0 0 10 0 -0 0</pose>
      </light>
      <light name='user_point_light_0'>
        <pose frame=''>4.12944 0.277426 1 0 -0 0</pose>
      </light>
    </state>
    <gui fullscreen='0'>
      <camera name='user_camera'>
        <pose frame=''>-0.029318 -5.509 5.27465 0 0.773797 1.2922</pose>
        <view_controller>orbit</view_controller>
        <projection_type>perspective</projection_type>
      </camera>
    </gui>
  </world>
</sdf>
